2024-05-21 00:40:34.011 | ERROR    | metagpt.utils.common:log_it:554 - Finished call to 'MCTS.Lingma.ask_llm_location_file.ChatGPT.chat' after 75.524(s), this was the 1st time calling it. exp: 请求失败。
Message: {"code":200,"data":"{\"error\":{\"message\":\"The server had an error processing your request. Sorry about that! You can retry your request, or contact us through our help center at help.openai.com if you keep seeing this error. (Please include the request ID req_1a9dc7d2559dc8bbbb50fca6fb41ca22 in your email.)\",\"type\":\"server_error\",\"param\":null,\"code\":null}}","message":"success"}

2024-05-21 00:44:07.100 | ERROR    | metagpt.utils.common:log_it:554 - Finished call to 'MCTS.Lingma.ask_llm_location_file.ChatGPT.get_reward' after 60.621(s), this was the 1st time calling it. exp: 请求失败。
Message: {"code":200,"data":"{\"error\":{\"message\":\"The server had an error processing your request. Sorry about that! You can retry your request, or contact us through our help center at help.openai.com if you keep seeing this error. (Please include the request ID req_ac843cb741294d8bdab2c437c671ac7a in your email.)\",\"type\":\"server_error\",\"param\":null,\"code\":null}}","message":"success"}

2024-05-21 00:47:19.240 | ERROR    | metagpt.utils.common:log_it:554 - Finished call to 'MCTS.Lingma.ask_llm_location_file.ChatGPT.get_reward' after 68.338(s), this was the 1st time calling it. exp: 请求失败。
Message: {"code":200,"data":"{\"error\":{\"message\":\"The server had an error processing your request. Sorry about that! You can retry your request, or contact us through our help center at help.openai.com if you keep seeing this error. (Please include the request ID req_0cc0d2e0a440d17c19deeadc3eec2dcf in your email.)\",\"type\":\"server_error\",\"param\":null,\"code\":null}}","message":"success"}

2024-05-21 01:24:19.569 | ERROR    | metagpt.utils.common:log_it:554 - Finished call to 'MCTS.Lingma.ask_llm_location_file.ChatGPT.ask_summary_results' after 110.215(s), this was the 1st time calling it. exp: 请求失败。
Message: {"code":500,"message":"服务器异常:'NoneType' object is not iterable"}

2024-05-21 01:51:54.733 | ERROR    | metagpt.utils.common:log_it:554 - Finished call to 'MCTS.Lingma.ask_llm_location_file.ChatGPT.get_reward' after 107.560(s), this was the 1st time calling it. exp: HTTPConnectionPool(host='47.88.8.18', port=8088): Read timed out. (read timeout=None)
2024-05-21 02:02:58.699 | ERROR    | metagpt.utils.common:log_it:554 - Finished call to 'MCTS.Lingma.ask_llm_location_file.ChatGPT.get_reward' after 110.404(s), this was the 1st time calling it. exp: 请求失败。
Message: {"code":200,"data":"{\"error\":{\"message\":\"The server had an error processing your request. Sorry about that! You can retry your request, or contact us through our help center at help.openai.com if you keep seeing this error. (Please include the request ID req_67e99ea8ebc61288d9ab2f2d51543788 in your email.)\",\"type\":\"server_error\",\"param\":null,\"code\":null}}","message":"success"}

2024-05-21 02:05:38.867 | ERROR    | metagpt.utils.common:log_it:554 - Finished call to 'MCTS.Lingma.ask_llm_location_file.ChatGPT.get_reward' after 97.315(s), this was the 1st time calling it. exp: 请求失败。
Message: {"code":200,"data":"{\"error\":{\"message\":\"The server had an error processing your request. Sorry about that! You can retry your request, or contact us through our help center at help.openai.com if you keep seeing this error. (Please include the request ID req_c4b9739771073756b74265dccaa37fd7 in your email.)\",\"type\":\"server_error\",\"param\":null,\"code\":null}}","message":"success"}

2024-05-21 02:56:31.648 | ERROR    | metagpt.utils.common:log_it:554 - Finished call to 'MCTS.Lingma.ask_llm_location_file.ChatGPT.get_reward' after 100.027(s), this was the 1st time calling it. exp: HTTPConnectionPool(host='47.88.8.18', port=8088): Read timed out. (read timeout=None)
2024-05-21 03:26:32.410 | ERROR    | metagpt.utils.common:log_it:554 - Finished call to 'MCTS.Lingma.ask_llm_location_file.ChatGPT.get_reward' after 16.981(s), this was the 1st time calling it. exp: no score found for The provided issue is about a crash that occurs when remaking a table with a unique constraint, specifically in a SQLite environment, using Django's migration system. The stack trace shows an OperationalError raised with the message "the '.' operator prohibited in index expressions," which is indicative of a problem with how the unique constraint is being handled within the SQLite backend.

Now, let’s analyze the provided code:

The provided code snippet is from the `pre_save` method of Django's `FileField` class, which handles file storage actions in models before saving an instance.

```python
def pre_save(self, model_instance, add):
    file = super().pre_save(model_instance, add)
    if file and not file._committed:
        # Commit the file to storage prior to saving the model
        file.save(file.name, file.file, save=False)
    return file
```

This method's responsibility is to ensure that a file associated with a `FileField` is saved to its storage system before the model instance itself is saved. 

However, the issue at hand does not concern how files are handled in Django models. Instead, it's related to Django's ORM layer, particularly with respect to the process of altering field definitions and handling database constraints during migrations. The error specifically points towards SQLite's handling of index expressions, which might stem from the Django SQLite schema backend that manages database operations such as creating and altering tables.

The `pre_save` method and the issue are unrelated, as the error is specific to database migrations, table modifications, and constraint definitions, particularly within the internals of SQLite's schema operations in Django. Therefore, this code is not a potential cause of the issue described and would not be the location to look for the bug or implement a fix.

In conclusion, this code does not need to be modified to resolve the described issue.
2024-05-21 08:41:25.866 | ERROR    | metagpt.utils.common:log_it:554 - Finished call to 'MCTS.Lingma.ask_llm_location_file.ChatGPT.get_reward' after 11.833(s), this was the 1st time calling it. exp: 请求失败。
Message: {"code":500,"message":"服务器异常:'NoneType' object is not iterable"}

2024-05-21 10:12:24.215 | ERROR    | metagpt.utils.common:log_it:554 - Finished call to 'MCTS.Lingma.ask_llm_location_file.ChatGPT.get_reward' after 18.405(s), this was the 1st time calling it. exp: no score found for The reported issue states that attempting to create a polynomial with `domain='RR[y,z]'` fails with an `OptionError`, indicating that the domain specification is invalid. The exception is raised as the provided domain is not recognized by the system. Indeed, this error is specific to the polynomial domain handling within the Sympy library.

The provided code snippet appears to be a method named `default` within a class named `Option`, situated in the `sympy/polys/polyoptions.py` file. This method seems to define a default value (which is `None`) for an option in a class that handles polynomial options.

The actual issue, however, seems to stem from domain processing, likely within the `Options` class or related functions that handle domain specifications. The root of the problem could be around areas where domains are interpreted, validated, or instantiated. Such code would normally be a method or function that takes a domain specification and attempts to convert it into an internal representation or validate it against known valid domains.

Without the full context of where the `OptionError` is being raised and the actual implementation details of the domain validation process, we have insufficient information to pinpoint the exact location in the code that needs modification. It is, however, reasonable to assume that the code responsible for handling, validating, or converting domain specifications to internal representations is likely where the fix is required.

The given `default` method in the `Option` class does not appear to be related directly to domain specification or validation. Most likely, the actual buggy code would be somewhere in the same file (`sympy/polys/polyoptions.py`) or in related modules that parse and validate the options (in this case, the domain).

Result: Thus the probability score that this specific `default` method code needs to be modified to solve the issue is likely low, probably around 2, as it seems to have an ancillary role. However, it is to be noted that other parts of the `polyoptions.py` file, not provided here, are likely candidates for modification to resolve the domain specification issue.
2024-05-21 10:40:20.493 | ERROR    | metagpt.utils.common:log_it:554 - Finished call to 'MCTS.Lingma.ask_llm_location_file.ChatGPT.get_reward' after 2.405(s), this was the 1st time calling it. exp: no score found for The issue reported
2024-05-21 10:41:57.534 | ERROR    | metagpt.utils.common:log_it:554 - Finished call to 'MCTS.Lingma.ask_llm_location_file.ChatGPT.get_reward' after 1.942(s), this was the 1st time calling it. exp: no score found for The issue described suggests that
2024-05-21 10:41:58.007 | ERROR    | metagpt.utils.common:log_it:554 - Finished call to 'MCTS.Lingma.ask_llm_location_file.ChatGPT.get_reward' after 2.731(s), this was the 1st time calling it. exp: no score found for The issue described is related to the
2024-05-21 10:41:59.870 | ERROR    | metagpt.utils.common:log_it:554 - Finished call to 'MCTS.Lingma.ask_llm_location_file.ChatGPT.get_reward' after 0.728(s), this was the 1st time calling it. exp: 请求失败。
Message: {"code":200,"data":"{\"timestamp\":\"2024-05-21T02:41:59.708+00:00\",\"status\":500,\"error\":\"Internal Server Error\",\"path\":\"/proxy/v1/chat/completions\"}","message":"success"}

2024-05-21 10:42:05.503 | ERROR    | metagpt.utils.common:log_it:554 - Finished call to 'MCTS.Lingma.ask_llm_location_file.ChatGPT.get_reward' after 6.362(s), this was the 2nd time calling it. exp: no score found for The issue presented
2024-05-21 10:42:30.765 | ERROR    | metagpt.utils.common:log_it:554 - Finished call to 'MCTS.Lingma.ask_llm_location_file.ChatGPT.get_reward' after 1.106(s), this was the 1st time calling it. exp: 请求失败。
Message: {"code":200,"data":"{\"timestamp\":\"2024-05-21T02:42:30.615+00:00\",\"status\":500,\"error\":\"Internal Server Error\",\"path\":\"/proxy/v1/chat/completions\"}","message":"success"}

2024-05-21 10:42:31.706 | ERROR    | metagpt.utils.common:log_it:554 - Finished call to 'MCTS.Lingma.ask_llm_location_file.ChatGPT.get_reward' after 2.050(s), this was the 1st time calling it. exp: no score found for The
2024-05-21 10:42:31.800 | ERROR    | metagpt.utils.common:log_it:554 - Finished call to 'MCTS.Lingma.ask_llm_location_file.ChatGPT.get_reward' after 0.701(s), this was the 1st time calling it. exp: 请求失败。
Message: {"code":200,"data":"{\"timestamp\":\"2024-05-21T02:42:31.641+00:00\",\"status\":500,\"error\":\"Internal Server Error\",\"path\":\"/proxy/v1/chat/completions\"}","message":"success"}

2024-05-21 10:42:39.558 | ERROR    | metagpt.utils.common:log_it:554 - Finished call to 'MCTS.Lingma.ask_llm_location_file.ChatGPT.get_reward' after 1.077(s), this was the 1st time calling it. exp: 请求失败。
Message: {"code":200,"data":"{\"timestamp\":\"2024-05-21T02:42:39.062+00:00\",\"status\":500,\"error\":\"Internal Server Error\",\"path\":\"/proxy/v1/chat/completions\"}","message":"success"}

2024-05-21 10:42:39.561 | ERROR    | metagpt.utils.common:log_it:554 - Finished call to 'MCTS.Lingma.ask_llm_location_file.ChatGPT.get_reward' after 1.080(s), this was the 1st time calling it. exp: 请求失败。
Message: {"code":200,"data":"{\"timestamp\":\"2024-05-21T02:42:39.130+00:00\",\"status\":500,\"error\":\"Internal Server Error\",\"path\":\"/proxy/v1/chat/completions\"}","message":"success"}

2024-05-21 10:42:40.108 | ERROR    | metagpt.utils.common:log_it:554 - Finished call to 'MCTS.Lingma.ask_llm_location_file.ChatGPT.get_reward' after 1.286(s), this was the 1st time calling it. exp: 请求失败。
Message: {"code":200,"data":"{\"timestamp\":\"2024-05-21T02:42:39.949+00:00\",\"status\":500,\"error\":\"Internal Server Error\",\"path\":\"/proxy/v1/chat/completions\"}","message":"success"}

2024-05-21 10:42:40.119 | ERROR    | metagpt.utils.common:log_it:554 - Finished call to 'MCTS.Lingma.ask_llm_location_file.ChatGPT.get_reward' after 1.298(s), this was the 1st time calling it. exp: 请求失败。
Message: {"code":200,"data":"{\"timestamp\":\"2024-05-21T02:42:39.974+00:00\",\"status\":500,\"error\":\"Internal Server Error\",\"path\":\"/proxy/v1/chat/completions\"}","message":"success"}

2024-05-21 10:42:40.476 | ERROR    | metagpt.utils.common:log_it:554 - Finished call to 'MCTS.Lingma.ask_llm_location_file.ChatGPT.get_reward' after 1.994(s), this was the 1st time calling it. exp: no score found for The issue describes
2024-05-21 10:42:40.532 | ERROR    | metagpt.utils.common:log_it:554 - Finished call to 'MCTS.Lingma.ask_llm_location_file.ChatGPT.get_reward' after 10.873(s), this was the 2nd time calling it. exp: 请求失败。
Message: {"code":200,"data":"{\"timestamp\":\"2024-05-21T02:42:40.383+00:00\",\"status\":500,\"error\":\"Internal Server Error\",\"path\":\"/proxy/v1/chat/completions\"}","message":"success"}

2024-05-21 10:42:41.390 | ERROR    | metagpt.utils.common:log_it:554 - Finished call to 'MCTS.Lingma.ask_llm_location_file.ChatGPT.get_reward' after 2.570(s), this was the 1st time calling it. exp: no score found for The issue described pertains
2024-05-21 10:42:44.169 | ERROR    | metagpt.utils.common:log_it:554 - Finished call to 'MCTS.Lingma.ask_llm_location_file.ChatGPT.get_reward' after 5.348(s), this was the 2nd time calling it. exp: 请求失败。
Message: {"code":200,"data":"{\"timestamp\":\"2024-05-21T02:42:43.888+00:00\",\"status\":500,\"error\":\"Internal Server Error\",\"path\":\"/proxy/v1/chat/completions\"}","message":"success"}

2024-05-21 10:42:48.765 | ERROR    | metagpt.utils.common:log_it:554 - Finished call to 'MCTS.Lingma.ask_llm_location_file.ChatGPT.get_reward' after 9.942(s), this was the 2nd time calling it. exp: 请求失败。
Message: {"code":200,"data":"{\"timestamp\":\"2024-05-21T02:42:48.616+00:00\",\"status\":500,\"error\":\"Internal Server Error\",\"path\":\"/proxy/v1/chat/completions\"}","message":"success"}

2024-05-21 10:43:04.482 | ERROR    | metagpt.utils.common:log_it:554 - Finished call to 'MCTS.Lingma.ask_llm_location_file.ChatGPT.get_reward' after 2.138(s), this was the 1st time calling it. exp: 请求失败。
Message: {"code":200,"data":"{\"timestamp\":\"2024-05-21T02:43:04.324+00:00\",\"status\":500,\"error\":\"Internal Server Error\",\"path\":\"/proxy/v1/chat/completions\"}","message":"success"}

2024-05-21 10:43:26.731 | ERROR    | metagpt.utils.common:log_it:554 - Finished call to 'MCTS.Lingma.ask_llm_location_file.ChatGPT.get_reward' after 0.920(s), this was the 1st time calling it. exp: 请求失败。
Message: {"code":200,"data":"{\"timestamp\":\"2024-05-21T02:43:26.567+00:00\",\"status\":500,\"error\":\"Internal Server Error\",\"path\":\"/proxy/v1/chat/completions\"}","message":"success"}

2024-05-21 10:50:26.415 | ERROR    | metagpt.utils.common:log_it:554 - Finished call to 'MCTS.Lingma.ask_llm_location_file.ChatGPT.get_reward' after 2.192(s), this was the 1st time calling it. exp: no score found for The issue describes a renaming
2024-05-21 10:50:35.578 | ERROR    | metagpt.utils.common:log_it:554 - Finished call to 'MCTS.Lingma.ask_llm_location_file.ChatGPT.get_reward' after 1.819(s), this was the 1st time calling it. exp: no score found for The issue provided
2024-05-21 10:50:36.025 | ERROR    | metagpt.utils.common:log_it:554 - Finished call to 'MCTS.Lingma.ask_llm_location_file.ChatGPT.get_reward' after 2.260(s), this was the 1st time calling it. exp: no score found for The reported issue
2024-05-21 10:50:49.443 | ERROR    | metagpt.utils.common:log_it:554 - Finished call to 'MCTS.Lingma.ask_llm_location_file.ChatGPT.get_reward' after 2.022(s), this was the 1st time calling it. exp: no score found for The issue described is for
2024-05-21 10:50:58.931 | ERROR    | metagpt.utils.common:log_it:554 - Finished call to 'MCTS.Lingma.ask_llm_location_file.ChatGPT.get_reward' after 0.873(s), this was the 1st time calling it. exp: 请求失败。
Message: {"code":200,"data":"{\"timestamp\":\"2024-05-21T02:50:58.770+00:00\",\"status\":500,\"error\":\"Internal Server Error\",\"path\":\"/proxy/v1/chat/completions\"}","message":"success"}

2024-05-21 10:50:59.952 | ERROR    | metagpt.utils.common:log_it:554 - Finished call to 'MCTS.Lingma.ask_llm_location_file.ChatGPT.get_reward' after 1.892(s), this was the 1st time calling it. exp: no score found for The
2024-05-21 10:51:16.355 | ERROR    | metagpt.utils.common:log_it:554 - Finished call to 'MCTS.Lingma.ask_llm_location_file.ChatGPT.get_reward' after 0.790(s), this was the 1st time calling it. exp: 请求失败。
Message: {"code":200,"data":"{\"timestamp\":\"2024-05-21T02:51:16.190+00:00\",\"status\":500,\"error\":\"Internal Server Error\",\"path\":\"/proxy/v1/chat/completions\"}","message":"success"}

2024-05-21 10:51:20.230 | ERROR    | metagpt.utils.common:log_it:554 - Finished call to 'MCTS.Lingma.ask_llm_location_file.ChatGPT.get_reward' after 0.792(s), this was the 1st time calling it. exp: 请求失败。
Message: {"code":200,"data":"{\"timestamp\":\"2024-05-21T02:51:20.007+00:00\",\"status\":500,\"error\":\"Internal Server Error\",\"path\":\"/proxy/v1/chat/completions\"}","message":"success"}

2024-05-21 10:51:37.595 | ERROR    | metagpt.utils.common:log_it:554 - Finished call to 'MCTS.Lingma.ask_llm_location_file.ChatGPT.get_reward' after 0.924(s), this was the 1st time calling it. exp: 请求失败。
Message: {"code":200,"data":"{\"timestamp\":\"2024-05-21T02:51:37.375+00:00\",\"status\":500,\"error\":\"Internal Server Error\",\"path\":\"/proxy/v1/chat/completions\"}","message":"success"}

2024-05-21 10:51:59.699 | ERROR    | metagpt.utils.common:log_it:554 - Finished call to 'MCTS.Lingma.ask_llm_location_file.ChatGPT.get_reward' after 0.772(s), this was the 1st time calling it. exp: 请求失败。
Message: {"code":200,"data":"{\"timestamp\":\"2024-05-21T02:51:59.540+00:00\",\"status\":500,\"error\":\"Internal Server Error\",\"path\":\"/proxy/v1/chat/completions\"}","message":"success"}

2024-05-21 10:51:59.702 | ERROR    | metagpt.utils.common:log_it:554 - Finished call to 'MCTS.Lingma.ask_llm_location_file.ChatGPT.get_reward' after 0.778(s), this was the 1st time calling it. exp: 请求失败。
Message: {"code":200,"data":"{\"timestamp\":\"2024-05-21T02:51:59.544+00:00\",\"status\":500,\"error\":\"Internal Server Error\",\"path\":\"/proxy/v1/chat/completions\"}","message":"success"}

2024-05-21 10:51:59.711 | ERROR    | metagpt.utils.common:log_it:554 - Finished call to 'MCTS.Lingma.ask_llm_location_file.ChatGPT.get_reward' after 0.787(s), this was the 1st time calling it. exp: 请求失败。
Message: {"code":200,"data":"{\"timestamp\":\"2024-05-21T02:51:59.561+00:00\",\"status\":500,\"error\":\"Internal Server Error\",\"path\":\"/proxy/v1/chat/completions\"}","message":"success"}

2024-05-21 10:52:01.450 | ERROR    | metagpt.utils.common:log_it:554 - Finished call to 'MCTS.Lingma.ask_llm_location_file.ChatGPT.get_reward' after 2.526(s), this was the 2nd time calling it. exp: 请求失败。
Message: {"code":200,"data":"{\"timestamp\":\"2024-05-21T02:52:00.935+00:00\",\"status\":500,\"error\":\"Internal Server Error\",\"path\":\"/proxy/v1/chat/completions\"}","message":"success"}

2024-05-21 10:55:39.266 | ERROR    | metagpt.utils.common:log_it:554 - Finished call to 'MCTS.Lingma.ask_llm_location_file.ChatGPT.get_reward' after 0.910(s), this was the 1st time calling it. exp: 请求失败。
Message: {"code":200,"data":"{\"timestamp\":\"2024-05-21T02:55:39.122+00:00\",\"status\":500,\"error\":\"Internal Server Error\",\"path\":\"/proxy/v1/chat/completions\"}","message":"success"}

2024-05-21 10:55:39.267 | ERROR    | metagpt.utils.common:log_it:554 - Finished call to 'MCTS.Lingma.ask_llm_location_file.ChatGPT.get_reward' after 0.913(s), this was the 1st time calling it. exp: 请求失败。
Message: {"code":200,"data":"{\"timestamp\":\"2024-05-21T02:55:39.148+00:00\",\"status\":500,\"error\":\"Internal Server Error\",\"path\":\"/proxy/v1/chat/completions\"}","message":"success"}

2024-05-21 10:55:41.687 | ERROR    | metagpt.utils.common:log_it:554 - Finished call to 'MCTS.Lingma.ask_llm_location_file.ChatGPT.get_reward' after 3.332(s), this was the 2nd time calling it. exp: 请求失败。
Message: {"code":200,"data":"{\"timestamp\":\"2024-05-21T02:55:41.292+00:00\",\"status\":500,\"error\":\"Internal Server Error\",\"path\":\"/proxy/v1/chat/completions\"}","message":"success"}

2024-05-21 10:55:51.164 | ERROR    | metagpt.utils.common:log_it:554 - Finished call to 'MCTS.Lingma.ask_llm_location_file.ChatGPT.get_reward' after 12.804(s), this was the 3rd time calling it. exp: 请求失败。
Message: {"code":200,"data":"{\"timestamp\":\"2024-05-21T02:55:50.800+00:00\",\"status\":500,\"error\":\"Internal Server Error\",\"path\":\"/proxy/v1/chat/completions\"}","message":"success"}

2024-05-21 10:56:26.632 | ERROR    | metagpt.utils.common:log_it:554 - Finished call to 'MCTS.Lingma.ask_llm_location_file.ChatGPT.chat' after 1.187(s), this was the 1st time calling it. exp: 请求失败。
Message: {"code":200,"data":"{\"timestamp\":\"2024-05-21T02:56:26.444+00:00\",\"status\":500,\"error\":\"Internal Server Error\",\"path\":\"/proxy/v1/chat/completions\"}","message":"success"}

2024-05-21 11:03:08.358 | ERROR    | metagpt.utils.common:log_it:554 - Finished call to 'MCTS.Lingma.ask_llm_location_file.ChatGPT.get_reward' after 0.816(s), this was the 1st time calling it. exp: 请求失败。
Message: {"code":200,"data":"{\"timestamp\":\"2024-05-21T03:03:08.269+00:00\",\"status\":500,\"error\":\"Internal Server Error\",\"path\":\"/proxy/v1/chat/completions\"}","message":"success"}

2024-05-21 11:03:17.405 | ERROR    | metagpt.utils.common:log_it:554 - Finished call to 'MCTS.Lingma.ask_llm_location_file.ChatGPT.get_reward' after 0.885(s), this was the 1st time calling it. exp: 请求失败。
Message: {"code":200,"data":"{\"timestamp\":\"2024-05-21T03:03:17.317+00:00\",\"status\":500,\"error\":\"Internal Server Error\",\"path\":\"/proxy/v1/chat/completions\"}","message":"success"}

2024-05-21 11:03:17.406 | ERROR    | metagpt.utils.common:log_it:554 - Finished call to 'MCTS.Lingma.ask_llm_location_file.ChatGPT.get_reward' after 0.890(s), this was the 1st time calling it. exp: 请求失败。
Message: {"code":200,"data":"{\"timestamp\":\"2024-05-21T03:03:17.314+00:00\",\"status\":500,\"error\":\"Internal Server Error\",\"path\":\"/proxy/v1/chat/completions\"}","message":"success"}

2024-05-21 11:03:26.365 | ERROR    | metagpt.utils.common:log_it:554 - Finished call to 'MCTS.Lingma.ask_llm_location_file.ChatGPT.get_reward' after 9.846(s), this was the 2nd time calling it. exp: 请求失败。
Message: {"code":200,"data":"{\"timestamp\":\"2024-05-21T03:03:26.276+00:00\",\"status\":500,\"error\":\"Internal Server Error\",\"path\":\"/proxy/v1/chat/completions\"}","message":"success"}

2024-05-21 11:03:53.616 | ERROR    | metagpt.utils.common:log_it:554 - Finished call to 'MCTS.Lingma.ask_llm_location_file.ChatGPT.get_reward' after 3.666(s), this was the 1st time calling it. exp: no score found for The
2024-05-21 11:03:57.614 | ERROR    | metagpt.utils.common:log_it:554 - Finished call to 'MCTS.Lingma.ask_llm_location_file.ChatGPT.chat' after 1.021(s), this was the 1st time calling it. exp: 请求失败。
Message: {"code":200,"data":"{\"timestamp\":\"2024-05-21T03:03:57.408+00:00\",\"status\":500,\"error\":\"Internal Server Error\",\"path\":\"/proxy/v1/chat/completions\"}","message":"success"}

2024-05-21 12:09:04.800 | ERROR    | metagpt.utils.common:log_it:554 - Finished call to 'MCTS.Lingma.ask_llm_location_file.ChatGPT.get_reward' after 0.744(s), this was the 1st time calling it. exp: 请求失败。
Message: {"code":200,"data":"<!DOCTYPE HTML PUBLIC \"-//IETF//DTD HTML 2.0//EN\">\r\n<html>\r\n<head><title>502 Bad Gateway</title></head>\r\n<body>\r\n<h1>502 Bad Gateway</h1>\r\n<p>The proxy server received an invalid response from an upstream server.<hr/>Powered by Tengine</body>\r\n</html>\r\n","message":"success"}

2024-05-21 12:24:13.581 | ERROR    | metagpt.utils.common:log_it:554 - Finished call to 'MCTS.Lingma.ask_llm_location_file.ChatGPT.get_reward' after 302.695(s), this was the 1st time calling it. exp: 请求失败。
Message: {"code":500,"message":"服务器异常:('Connection broken: IncompleteRead(0 bytes read)', IncompleteRead(0 bytes read))"}

2024-05-21 13:47:39.756 | ERROR    | metagpt.utils.common:log_it:554 - Finished call to 'MCTS.Lingma.ask_llm_location_file.ChatGPT.get_reward' after 325.423(s), this was the 1st time calling it. exp: 请求失败。
Message: {"code":500,"message":"服务器异常:('Connection broken: IncompleteRead(0 bytes read)', IncompleteRead(0 bytes read))"}

2024-05-21 13:49:37.530 | ERROR    | metagpt.utils.common:log_it:554 - Finished call to 'MCTS.Lingma.ask_llm_location_file.ChatGPT.get_reward' after 351.545(s), this was the 1st time calling it. exp: 请求失败。
Message: {"code":500,"message":"服务器异常:('Connection broken: IncompleteRead(0 bytes read)', IncompleteRead(0 bytes read))"}

2024-05-21 14:17:50.911 | ERROR    | metagpt.utils.common:log_it:554 - Finished call to 'MCTS.Lingma.ask_llm_location_file.ChatGPT.get_reward' after 0.757(s), this was the 1st time calling it. exp: 请求失败。
Message: {"code":200,"data":"{\"timestamp\":\"2024-05-21T06:17:51.004+00:00\",\"status\":500,\"error\":\"Internal Server Error\",\"path\":\"/proxy/v1/chat/completions\"}","message":"success"}

2024-05-21 14:17:50.949 | ERROR    | metagpt.utils.common:log_it:554 - Finished call to 'MCTS.Lingma.ask_llm_location_file.ChatGPT.get_reward' after 0.791(s), this was the 1st time calling it. exp: 请求失败。
Message: {"code":200,"data":"{\"timestamp\":\"2024-05-21T06:17:51.021+00:00\",\"status\":500,\"error\":\"Internal Server Error\",\"path\":\"/proxy/v1/chat/completions\"}","message":"success"}

2024-05-21 14:17:52.492 | ERROR    | metagpt.utils.common:log_it:554 - Finished call to 'MCTS.Lingma.ask_llm_location_file.ChatGPT.get_reward' after 2.337(s), this was the 1st time calling it. exp: no score found for The provided issue
2024-05-21 14:18:01.061 | ERROR    | metagpt.utils.common:log_it:554 - Finished call to 'MCTS.Lingma.ask_llm_location_file.ChatGPT.get_reward' after 10.907(s), this was the 2nd time calling it. exp: no score found for The issue reports
2024-05-21 14:18:20.688 | ERROR    | metagpt.utils.common:log_it:554 - Finished call to 'MCTS.Lingma.ask_llm_location_file.ChatGPT.get_reward' after 0.773(s), this was the 1st time calling it. exp: 请求失败。
Message: {"code":200,"data":"{\"timestamp\":\"2024-05-21T06:18:20.753+00:00\",\"status\":500,\"error\":\"Internal Server Error\",\"path\":\"/proxy/v1/chat/completions\"}","message":"success"}

2024-05-21 14:18:21.609 | ERROR    | metagpt.utils.common:log_it:554 - Finished call to 'MCTS.Lingma.ask_llm_location_file.ChatGPT.get_reward' after 1.723(s), this was the 1st time calling it. exp: no score found for The issue presented is concerned
2024-05-21 14:18:21.914 | ERROR    | metagpt.utils.common:log_it:554 - Finished call to 'MCTS.Lingma.ask_llm_location_file.ChatGPT.get_reward' after 2.033(s), this was the 1st time calling it. exp: no score found for The issue reported
2024-05-21 14:23:23.977 | ERROR    | metagpt.utils.common:log_it:554 - Finished call to 'MCTS.Lingma.ask_llm_location_file.ChatGPT.get_reward' after 304.057(s), this was the 1st time calling it. exp: 请求失败。
Message: {"code":500,"message":"服务器异常:('Connection broken: IncompleteRead(0 bytes read)', IncompleteRead(0 bytes read))"}

2024-05-21 14:58:10.248 | ERROR    | metagpt.utils.common:log_it:554 - Finished call to 'MCTS.Lingma.ask_llm_location_file.ChatGPT.get_reward' after 319.559(s), this was the 1st time calling it. exp: 请求失败。
Message: {"code":500,"message":"服务器异常:('Connection broken: IncompleteRead(0 bytes read)', IncompleteRead(0 bytes read))"}

2024-05-21 15:37:05.558 | ERROR    | metagpt.utils.common:log_it:554 - Finished call to 'MCTS.Lingma.ask_llm_location_file.ChatGPT.get_reward' after 2.570(s), this was the 1st time calling it. exp: no score found for The issue centers
2024-05-21 15:38:16.075 | ERROR    | metagpt.utils.common:log_it:554 - Finished call to 'MCTS.Lingma.ask_llm_location_file.ChatGPT.get_reward' after 0.706(s), this was the 1st time calling it. exp: 请求失败。
Message: {"code":200,"data":"{\"timestamp\":\"2024-05-21T07:38:16.137+00:00\",\"status\":500,\"error\":\"Internal Server Error\",\"path\":\"/proxy/v1/chat/completions\"}","message":"success"}

2024-05-21 15:42:24.397 | ERROR    | metagpt.utils.common:log_it:554 - Finished call to 'MCTS.Lingma.ask_llm_location_file.ChatGPT.get_reward' after 330.145(s), this was the 1st time calling it. exp: 请求失败。
Message: {"code":500,"message":"服务器异常:('Connection broken: IncompleteRead(0 bytes read)', IncompleteRead(0 bytes read))"}

2024-05-21 15:43:27.794 | ERROR    | metagpt.utils.common:log_it:554 - Finished call to 'MCTS.Lingma.ask_llm_location_file.ChatGPT.get_reward' after 321.954(s), this was the 1st time calling it. exp: 请求失败。
Message: {"code":500,"message":"服务器异常:('Connection broken: IncompleteRead(0 bytes read)', IncompleteRead(0 bytes read))"}

2024-05-21 15:58:39.878 | ERROR    | metagpt.utils.common:log_it:554 - Finished call to 'MCTS.Lingma.ask_llm_location_file.ChatGPT.get_reward' after 320.507(s), this was the 1st time calling it. exp: 请求失败。
Message: {"code":500,"message":"服务器异常:('Connection broken: IncompleteRead(0 bytes read)', IncompleteRead(0 bytes read))"}

2024-05-21 15:59:00.195 | ERROR    | metagpt.utils.common:log_it:554 - Finished call to 'MCTS.Lingma.ask_llm_location_file.ChatGPT.get_reward' after 325.623(s), this was the 1st time calling it. exp: 请求失败。
Message: {"code":500,"message":"服务器异常:('Connection broken: IncompleteRead(0 bytes read)', IncompleteRead(0 bytes read))"}

2024-05-21 16:00:45.248 | ERROR    | metagpt.utils.common:log_it:554 - Finished call to 'MCTS.Lingma.ask_llm_location_file.ChatGPT.get_reward' after 321.956(s), this was the 1st time calling it. exp: 请求失败。
Message: {"code":500,"message":"服务器异常:('Connection broken: IncompleteRead(0 bytes read)', IncompleteRead(0 bytes read))"}

2024-05-21 16:23:40.357 | ERROR    | metagpt.utils.common:log_it:554 - Finished call to 'MCTS.Lingma.ask_llm_location_file.ChatGPT.get_reward' after 17.096(s), this was the 1st time calling it. exp: no score found for The reported issue is regarding the symbolic mathematics library, Sympy. Specifically, it's about an inconsistency in the simplification of expressions of the form `(-a)**x * a**(-x)` where `a` is a positive integer. There seems to be a discrepancy when a specific value for `a` is substituted before versus after the simplification.

The code segment provided is from the file `sympy/simplify/fu.py`, specifically just a line defining `CTR1` which seemingly relates to simplification rule sets `TR5`, `TR6`, and `identity`. This is very limited information and without the specific context or additional code, it's hard to determine if `CTR1` directly equates to the simplification issue. Nevertheless, given the provided code segment alone, we cannot conclusively say it's related to the issue in question, which concerns simplification inconsistency. It's possible that `CTR1` relates to the transformation rules being applied during the simplification process, but the snippet doesn't provide visibility into how `TR5`, `TR6`, or `identity` are defined or used.

In conclusion, without additional code that shows the definitions of `TR5`, `TR6`, the `identity` transformation, and the actual process of simplifying expressions in Sympy, determining if `CTR1` specifically pertains to this issue is speculative. Hence, the probability score that this particular code segment (`CTR1` definition) needs to be modified to solve the reported issue cannot be accurately determined based on the current information. However, this does not preclude the possibility that the simplification rules or algorithms used by Sympy elsewhere in the code might indeed need to be altered to address the issue.

As such, the probability score that this code needs to be modified to solve the issue hinges on the specific implementation details of the simplification process, which are not present in the given snippet.

Result: Thus the probability score that this code needs to be modified to solve this issue is uncertain based on the given snippet, and given this, I would tentatively score it as a 3, acknowledging that related code not currently seen may significantly adjust this score.
2024-05-21 16:34:04.153 | ERROR    | metagpt.utils.common:log_it:554 - Finished call to 'MCTS.Lingma.ask_llm_location_file.ChatGPT.get_reward' after 1.743(s), this was the 1st time calling it. exp: no score found for The given issue discusses the
2024-05-21 17:17:32.462 | ERROR    | metagpt.utils.common:log_it:554 - Finished call to 'MCTS.Lingma.ask_llm_location_file.ChatGPT.get_reward' after 16.162(s), this was the 1st time calling it. exp: no score found for To solve the reported issue, we must focus on the `ManagementUtility` class, specifically looking at how the `CommandParser` is instantiated. The issue states that the `CommandParser` should use `self.prog_name` instead of the program name from `sys.argv[0]`. The `fetch_command` function shown in the provided code is not the problematic code—it is responsible for fetching a command based on a subcommand string.

The provided code does not contain the instantiation of `CommandParser` where the actual issue is reported. Therefore, this particular piece of code is not the cause of the reported issue and does not need modification in relation to the provided issue. However, since we do not have access to other parts of the `ManagementUtility` class here, the code that needs to be modified is likely close to the `__init__` method of the class or another method where `CommandParser` is instantiated, rather than in the `fetch_command` method.

Since the provided code does not point to the correct location where the fix should be applied, we cannot provide a probability score related to its modification based on the given issue. It stands to reason that the code that should be modified is likely elsewhere in the `ManagementUtility` class where the `CommandParser` is instantiated with the incorrect `prog` argument.

Therefore, for the provided code a conclusion cannot be determined. To provide assistance, one would need to access the portion of the code that initializes the `CommandParser` and passes `sys.argv[0]` instead of `self.prog_name`.
2024-05-21 18:42:51.293 | ERROR    | metagpt.utils.common:log_it:554 - Finished call to 'MCTS.Lingma.ask_llm_location_file.ChatGPT.get_reward' after 313.388(s), this was the 1st time calling it. exp: 请求失败。
Message: {"code":500,"message":"服务器异常:('Connection broken: IncompleteRead(0 bytes read)', IncompleteRead(0 bytes read))"}

