2024-05-15 09:01:14.894 | ERROR    | metagpt.utils.common:log_it:554 - Finished call to 'MCTS.Lingma.ask_llm_location_file.ChatGPT.get_reward' after 19.656(s), this was the 1st time calling it. exp: no score found for The issue discusses a problem with the `__isnull` lookup in Django which should not allow non-boolean values. The code provided from `django/forms/models.py` relates to the `ModelChoiceField.to_python` method, which is tasked with converting input values into the appropriate Python objects based on the model's field definition but does not directly deal with query lookups like `__isnull`.

The usage of `__isnull` would typically be found in querysets or model queries where fields are being filtered based on
2024-05-15 09:24:57.473 | ERROR    | metagpt.utils.common:log_it:554 - Finished call to 'MCTS.Lingma.ask_llm_location_file.ChatGPT.chat' after 0.002(s), this was the 1st time calling it. exp: HTTPConnectionPool(host='47.88.8.18', port=8088): Max retries exceeded with url: /api/ask (Caused by NewConnectionError('<urllib3.connection.HTTPConnection object at 0x2a76d32d0>: Failed to establish a new connection: [Errno 51] Network is unreachable'))
2024-05-15 09:32:46.373 | ERROR    | metagpt.utils.common:log_it:554 - Finished call to 'MCTS.Lingma.ask_llm_location_file.ChatGPT.chat' after 31.991(s), this was the 2nd time calling it. exp: HTTPConnectionPool(host='47.88.8.18', port=8088): Max retries exceeded with url: /api/ask (Caused by NewConnectionError('<urllib3.connection.HTTPConnection object at 0x2a53477d0>: Failed to establish a new connection: [Errno 51] Network is unreachable'))
2024-05-15 09:34:40.398 | ERROR    | metagpt.utils.common:log_it:554 - Finished call to 'MCTS.Lingma.ask_llm_location_file.ChatGPT.chat' after 57.218(s), this was the 3rd time calling it. exp: HTTPConnectionPool(host='47.88.8.18', port=8088): Max retries exceeded with url: /api/ask (Caused by NewConnectionError('<urllib3.connection.HTTPConnection object at 0x111013310>: Failed to establish a new connection: [Errno 51] Network is unreachable'))
2024-05-15 09:34:40.831 | ERROR    | metagpt.utils.common:log_it:554 - Finished call to 'MCTS.Lingma.ask_llm_location_file.ChatGPT.chat' after 57.651(s), this was the 4th time calling it. exp: HTTPConnectionPool(host='47.88.8.18', port=8088): Max retries exceeded with url: /api/ask (Caused by NewConnectionError('<urllib3.connection.HTTPConnection object at 0x2a6834e10>: Failed to establish a new connection: [Errno 51] Network is unreachable'))
2024-05-15 09:38:06.445 | ERROR    | metagpt.utils.common:log_it:554 - Finished call to 'MCTS.Lingma.ask_llm_location_file.ChatGPT.chat' after 149.938(s), this was the 5th time calling it. exp: HTTPConnectionPool(host='47.88.8.18', port=8088): Max retries exceeded with url: /api/ask (Caused by ConnectTimeoutError(<urllib3.connection.HTTPConnection object at 0x2a4305050>, 'Connection to 47.88.8.18 timed out. (connect timeout=None)'))
2024-05-15 11:55:58.398 | ERROR    | metagpt.utils.common:log_it:554 - Finished call to 'MCTS.Lingma.ask_llm_location_file.ChatGPT.get_reward' after 2.446(s), this was the 1st time calling it. exp: no score found for The issue concerns the `app_list` context in a Django custom admin view and highlights the need for access to the model class within this context. It also suggests making
2024-05-15 12:04:06.743 | ERROR    | metagpt.utils.common:log_it:554 - Finished call to 'MCTS.Lingma.ask_llm_location_file.ChatGPT.get_reward' after 22.221(s), this was the 1st time calling it. exp: no score found for To examine the relevance of the provided code to the issue, the issue pertains to a failure encountered when setting `"TEST": {"MIGRATE": False}` in the database configurations for Django 3.1 and running tests using `./manage.py test`. The traceback suggests problems with database table relations and cursor operations during test database setup or teardown. The error messages specifically mention the absence of the "django_admin_log" relation and an invalid cursor name during test execution.

The provided code snippet belongs to the Django database utilities, specifically within the `ConnectionHandler` class's `__getitem__` method. This method is responsible for returning a database connection for the given alias. It checks if a connection for the alias already exists; if not, it proceeds to set up default settings for that alias, prepare test settings, and then initialize a new connection using the database backend specified in the Django settings.

Reviewing the nature of the failure and the role of the provided code, it appears the issue arises during the test database setup phase, potentially when Django attempts to skip migrations (`"MIGRATE": False`). Skipping migrations means the test database is created without running through the normal migrations that would establish tables
2024-05-15 13:02:20.482 | ERROR    | metagpt.utils.common:log_it:554 - Finished call to 'MCTS.Lingma.ask_llm_location_file.ChatGPT.get_reward' after 32.021(s), this was the 1st time calling it. exp: [Errno 32] Broken pipe
2024-05-15 13:03:07.324 | ERROR    | metagpt.utils.common:log_it:554 - Finished call to 'MCTS.Lingma.ask_llm_location_file.ChatGPT.get_reward' after 20.156(s), this was the 1st time calling it. exp: [Errno 32] Broken pipe
2024-05-15 13:03:37.389 | ERROR    | metagpt.utils.common:log_it:554 - Finished call to 'MCTS.Lingma.ask_llm_location_file.ChatGPT.get_reward' after 50.222(s), this was the 2nd time calling it. exp: [Errno 32] Broken pipe
2024-05-15 13:04:39.676 | ERROR    | metagpt.utils.common:log_it:554 - Finished call to 'MCTS.Lingma.ask_llm_location_file.ChatGPT.get_reward' after 17.647(s), this was the 1st time calling it. exp: [Errno 32] Broken pipe
2024-05-15 13:06:12.611 | ERROR    | metagpt.utils.common:log_it:554 - Finished call to 'MCTS.Lingma.ask_llm_location_file.ChatGPT.get_reward' after 21.155(s), this was the 1st time calling it. exp: [Errno 32] Broken pipe
2024-05-15 13:06:54.605 | ERROR    | metagpt.utils.common:log_it:554 - Finished call to 'MCTS.Lingma.ask_llm_location_file.ChatGPT.get_reward' after 32.588(s), this was the 1st time calling it. exp: [Errno 32] Broken pipe
2024-05-15 13:07:51.938 | ERROR    | metagpt.utils.common:log_it:554 - Finished call to 'MCTS.Lingma.ask_llm_location_file.ChatGPT.get_reward' after 31.911(s), this was the 1st time calling it. exp: [Errno 32] Broken pipe
2024-05-15 13:08:32.651 | ERROR    | metagpt.utils.common:log_it:554 - Finished call to 'MCTS.Lingma.ask_llm_location_file.ChatGPT.get_reward' after 20.259(s), this was the 1st time calling it. exp: [Errno 32] Broken pipe
2024-05-15 13:08:58.455 | ERROR    | metagpt.utils.common:log_it:554 - Finished call to 'MCTS.Lingma.ask_llm_location_file.ChatGPT.get_reward' after 46.064(s), this was the 1st time calling it. exp: [Errno 32] Broken pipe
2024-05-15 13:32:52.602 | ERROR    | metagpt.utils.common:log_it:554 - Finished call to 'MCTS.Lingma.ask_llm_location_file.ChatGPT.get_reward' after 61.538(s), this was the 1st time calling it. exp: 请求失败。
Message: {"code":200,"data":"{ \"error\": { \"code\": \"Timeout\", \"message\": \"The operation was timeout.\" } }","message":"success"}

2024-05-15 13:33:05.300 | ERROR    | metagpt.utils.common:log_it:554 - Finished call to 'MCTS.Lingma.ask_llm_location_file.ChatGPT.get_reward' after 87.124(s), this was the 1st time calling it. exp: no score found for The issue is specifically related to pickling figures in Matplotlib that have draggable elements, such as legends or annotations. The error message `TypeError: cannot pickle 'FigureCanvasQTAgg' object` indicates a problem in serializing (pickling) a figure to a byte stream, which occurs due to the presence of a draggable legend in the figure. The pickle operation is failing because some objects, particularly UI elements like the 'FigureCanvasQTAgg' mentioned in the error, contain non-pickleable components such as open file handles or threads.

The provided code snippet from the `FuncNorm` class in `lib/matplotlib/colors.py` file is unrelated to the issue at hand. It defines a class for applying arbitrary normalization using forward and inverse functions for data visualization. This functionality is part of Matplotlib's color mapping and normalization capabilities, which is separate from the figure's ability to serialize (pickle) its state, including UI components like draggable legends.

Serialization of objects, especially those involving UI elements in Matplotlib, is complex and might not directly relate to the functions or classes defined for data visualization, color normalization, or similar tasks. The issue likely stems from the broader architecture and implementation of objects within Matplotlib that are not designed to be easily pickled, particularly when UI interactivity is involved.

The `FuncNorm` class, focused on normalization for visualization, does not directly impact the pickling capabilities of figures with draggable elements. The failure in pickling is more likely associated with the broader design and implementation choices within Matplotlib, specifically how
2024-05-15 14:15:51.360 | ERROR    | metagpt.utils.common:log_it:554 - Finished call to 'MCTS.Lingma.ask_llm_location_file.ChatGPT.get_reward' after 18.956(s), this was the 1st time calling it. exp: no score found for The provided code snippet from `django/db/backends/sqlite3/base.py` is related to the explicit starting of a transaction under autocommit mode for the SQLite3 backend in Django. It is a backend-specific operation aimed at working around a bug in SQLite3 related to savepoints when autocommit is disabled. This method's responsibility is limited to transaction behavior and does not relate directly to how SQL queries, specifically subqueries, are generated or processed within Django's O
2024-05-15 14:38:30.371 | ERROR    | metagpt.utils.common:log_it:554 - Finished call to 'MCTS.Lingma.ask_llm_location_file.ChatGPT.get_reward' after 22.884(s), this was the 1st time calling it. exp: no score found for The issue describes a problem with the Django development server not restarting after a change is made to the `settings.py` file, specifically when the `BASE_DIR` variable is added to the `TEMPLATES[0]['DIRS']']` list. This bug affects the development server's ability to detect changes across the entire project, not just the `settings.py` file.

The provided code snippet from `django/utils/autoreload.py` pertains to the autoreload mechanism in Django, which is responsible for restarting the server when changes are detected in the codebase. The `request_processed` method seems to be linked to the process that sets an event indicating that a request has been processed, which might then influence or trigger the logic that checks for file changes to decide whether to restart the server.

Given the problem description, there is an indirect relationship between the autoreload mechanism, which the provided code is a part of, and the issue reported. The problem arises due to how changes in the `settings.py` file, specifically modifications to the `TEMPLATES[0]['DIRS']` configuration, affect the application's ability to notice changes and trigger a restart. As the reported issue is related to the development server's failure to restart upon file changes, the autoreload mechanism and its components, including the `request_processed` function, could be areas where modifications are needed to address this bug.

The exact cause of the problem might be deeper within the autoreload mechanism's file monitoring logic and how it interprets or fails to interpret changes when `BASE_DIR` is included in `TEMPLATES[0]['DIRS']`. The provided snippet alone is unlikely to be the sole flawed location needing correction. However, it forms part of the broader autoreload system that could require adjustments or bug fixes to solve the reported issue.

Thus, considering its role within the autoreload mechanism and potential indirect involvement in monitoring file changes, the probability score that this code (or closely related code in the autoreload system) needs to be modified to solve the issue is estimated to be 6.
2024-05-15 15:38:02.087 | ERROR    | metagpt.utils.common:log_it:554 - Finished call to 'MCTS.Lingma.ask_llm_location_file.ChatGPT.get_reward' after 14.514(s), this was the 1st time calling it. exp: no score found for The issue describes the need for adding a `nonform` CSS class for non-form errors in FormSets to align with the behavior of forms, which use a `nonfield` CSS class for non-field errors. This enhancement would assist developers in distinguishing between form field errors, non-field errors (forms), and non-form errors (FormSets) when rendering error messages. Therefore, the resolution requires an update in how Django's FormSets handle and display errors, notably in their error rendering mechanisms rather than the model field validation.

The provided code snippet is from the `Model` class in Django's `db/models/base.py` file and focuses on checking local fields during model validation. It is concerned with ensuring that fields referenced in model options (such as unique_together) actually exist and are of the correct type, rather than handling form or FormSet errors. This process is unrelated to form rendering or the handling/error reporting mechanisms in forms and FormSets. 

For addressing the issue, one should look into the parts of Django that deal with form and FormSet validation
2024-05-15 15:38:02.098 | ERROR    | metagpt.utils.common:log_it:554 - Finished call to 'MCTS.Lingma.ask_llm_location_file.ChatGPT.get_reward' after 14.525(s), this was the 1st time calling it. exp: no score found for The provided code snippet involves internal mechanisms related to saving model instances in Django, specifically ensuring data integrity when models with foreign key or one-to-one relationships are saved. It checks for unsaved related objects and handles cases where the related object's primary key (PK) may not be set or when the relationship keys have changed, to prevent data loss or corruption.

The issue, however, is focused on the user interface and presentation layer of Django applications. It requests the addition of a `nonform` CSS class to FormSets for handling non-form errors in a manner consistent with how individual forms handle non-field errors using a `nonfield` CSS class. This involves modifications likely in form rendering or error handling mechanisms at the form or formset level, rather than the database model saving process.

Given the specific focus on form rendering and error message presentation in the issue, and comparing that with the code's focus on saving model instances and maintaining data integrity at the database level, it's clear these two are addressing completely separate parts of the Django framework functionality.

The code provided does
2024-05-15 15:38:02.247 | ERROR    | metagpt.utils.common:log_it:554 - Finished call to 'MCTS.Lingma.ask_llm_location_file.ChatGPT.get_reward' after 14.672(s), this was the 1st time calling it. exp: no score found for The issue described is about enhancing the user interface and user experience when working with Django forms and FormSets by adding a `nonform` CSS class for non-form errors in FormSets. This feature request is focused on the presentation layer of form and FormSet errors, aiming to provide a consistent way to style error messages that are not associated with a specific form field. It is primarily related to the rendering and styling of error messages in the user interface, making it easier for developers to customize the appearance of these messages.

The provided code snippet is from the Django model’s base class, specifically the `_check_constraints` method. This method is concerned with checking database constraints associated with a Django model when the application is interacting with the database. It deals with various types of constraints such as check constraints, unique constraints with conditions, deferrable unique constraints, covering indexes, and expression indexes. The method generates warnings or errors if the database connection does not support certain features or if there are problems with the defined constraints.

Given the nature of the issue and the functionality of the
2024-05-15 16:14:12.184 | ERROR    | metagpt.utils.common:log_it:554 - Finished call to 'MCTS.Lingma.ask_llm_location_file.ChatGPT.get_reward' after 25.476(s), this was the 1st time calling it. exp: no score found for The presented issue focuses on an inequivalent expression simplification in SymPy, particularly involving the simplification process and numeric substitution into the expression `(-x/4 - S(1)/12)**x - 1`. The problem specifies that after applying the `simplify` method, the resulting expression behaves unexpectedly upon numeric substitution, yielding different results between the original and simplified forms with complex numbers involved in the outputs.

The referenced code segment from `sympy/core/expr.py` defines the `is_number` method within the `Expr` class. This method is designed to check if an expression has no free symbols and no undefined functions, essentially determining whether an expression represents a numeric value.

This `is_number` method, however, is not directly implicated in the simplification or evaluation process that leads to the inequivalent expressions stated in the issue. The simplification process (`simplify` function) and the evaluation or substitution process (`.subs()` method and `N()` function for numeric evaluation) involve different aspects of the SymPy library. Specifically, the `simplify` function involves symbolic manipulation to reduce expressions to simpler forms, and the `.subs()` method along with `N()` function are used for substituting symbols with values and numerically evaluating expressions, respectively.

The `is_number` method’s primary role is to assess whether an expression can be considered a numerical value, not to perform or directly affect simplification or evaluation/substitution procedures. While understanding the behavior of expressions in SymPy (e.g., determining if they qualify as a number after certain operations) is essential, the issue at hand involves deeper complexities in the symbolic manipulation and evaluation process that are not directly related to the logic within the `is_number` method.

Given that the reported issue deals with simplification to an inequivalent expression and the peculiarities of numeric substitution leading to different numerical outputs, the direct modification of the `is_number` method is unlikely to resolve the described problem. The issue is more closely related to the internal workings of the simplification algorithms and numeric evaluation routines within SymPy, which are beyond the scope of the `is_number` method’s responsibilities of just identifying numeric-like expressions.

_Result:_ Thus, the probability score that this code needs to be modified to solve this issue is **1**.
2024-05-15 16:38:05.945 | ERROR    | metagpt.utils.common:log_it:554 - Finished call to 'MCTS.Lingma.ask_llm_location_file.ChatGPT.get_reward' after 6.074(s), this was the 1st time calling it. exp: 请求失败。
Message: {"code":200,"data":"{\"timestamp\":\"2024-05-15T08:38:05.788+00:00\",\"status\":500,\"error\":\"Internal Server Error\",\"path\":\"/v1/chat/completions\"}","message":"success"}

2024-05-15 18:57:00.089 | ERROR    | metagpt.utils.common:log_it:554 - Finished call to 'MCTS.Lingma.ask_llm_location_file.ChatGPT.get_reward' after 30.166(s), this was the 1st time calling it. exp: no score found for To address the issue described, we need to understand the nature of the problem in the context of symbolic mathematics within the SymPy library. The issue reports an inconsistency when simplifying expressions of the form `(-a)**x * a**(-x)` where `a` is a positive integer. In the first example, `a` is defined symbolically with conditions that it is an integer and positive, and simplification yields `(-1)**x`. In the second example, `a` is concretely set as `2`, yet after simplification, evaluating the expression at `x = -10/3` gives different results for the initialized expression `(-a)**x * a**(-x)` and its simplified form `(-1)**x`.

The inconsistency likely arises from an incorrect assumption or rule within the simplification functions of SymPy that is not accounting for the complexities in evaluating powers of negative numbers when the exponent is not an integer, potentially leading to incorrect simplifications in some cases.

The code snippet provided is from the SymPy library, where `FU` is a dictionary that holds references to transformation functions used in the simplification process. However, without seeing the functions that might be causing the discrepancy or the specific part of the code that governs the simplification of expressions like `(-a)**x * a**(-x)`, it's impossible to directly identify if this snippet is related to the issue.

Since the code provided is a high-level structure connecting transformation functions rather than a part of the simplification logic itself, it is not necessarily the location where the fix would need to be applied. The actual bug is more likely to be in the implementation of the transformation functions associated with power simplification.

Given this context and the nature of the issue described, it appears that the problem is likely within the simplification rules for exponents and might require a detailed look at the transformation functions related to handling powers of expressions. 

Thus, the probability score that this specific code (`FU` dictionary definition) needs to be modified to solve this issue is low (1). However, one of the transformation functions referenced in this dictionary might indeed contain the error and thus would need to be modified to fix the reported inconsistency.
2024-05-15 19:16:41.191 | ERROR    | metagpt.utils.common:log_it:554 - Finished call to 'MCTS.Lingma.ask_llm_location_file.ChatGPT.get_reward' after 47.761(s), this was the 1st time calling it. exp: [Errno 32] Broken pipe
2024-05-15 19:48:30.899 | ERROR    | metagpt.utils.common:log_it:554 - Finished call to 'MCTS.Lingma.ask_llm_location_file.ChatGPT.get_reward' after 144.337(s), this was the 1st time calling it. exp: no score found for This issue revolves around the inability of Sphinx autodoc to resolve type annotations for `struct.Struct`. The problem described is specific to the documentation generation process where `struct
2024-05-15 23:07:49.407 | ERROR    | metagpt.utils.common:log_it:554 - Finished call to 'MCTS.Lingma.ask_llm_location_file.ChatGPT.chat' after 1.203(s), this was the 1st time calling it. exp: 请求失败。
Message: {"code":200,"data":"{\"error\":{\"code\":\"DeploymentNotFound\", \"message\":\"The API deployment for this resource does not exist. If you created the deployment within the last 5 minutes, please wait a moment and try again.\"}}","message":"success"}

2024-05-15 23:16:46.604 | ERROR    | metagpt.utils.common:log_it:554 - Finished call to 'MCTS.Lingma.ask_llm_location_file.ChatGPT.get_reward' after 0.731(s), this was the 1st time calling it. exp: 请求失败。
Message: {"code":200,"data":"{\"error\":{\"code\":\"DeploymentNotFound\", \"message\":\"The API deployment for this resource does not exist. If you created the deployment within the last 5 minutes, please wait a moment and try again.\"}}","message":"success"}

2024-05-15 23:17:21.467 | ERROR    | metagpt.utils.common:log_it:554 - Finished call to 'MCTS.Lingma.ask_llm_location_file.ChatGPT.get_reward' after 35.594(s), this was the 1st time calling it. exp: ('Connection aborted.', RemoteDisconnected('Remote end closed connection without response'))
2024-05-15 23:17:28.998 | ERROR    | metagpt.utils.common:log_it:554 - Finished call to 'MCTS.Lingma.ask_llm_location_file.ChatGPT.get_reward' after 43.124(s), this was the 1st time calling it. exp: ('Connection aborted.', RemoteDisconnected('Remote end closed connection without response'))
2024-05-15 23:17:34.220 | ERROR    | metagpt.utils.common:log_it:554 - Finished call to 'MCTS.Lingma.ask_llm_location_file.ChatGPT.get_reward' after 48.345(s), this was the 1st time calling it. exp: ('Connection aborted.', RemoteDisconnected('Remote end closed connection without response'))
2024-05-15 23:17:53.676 | ERROR    | metagpt.utils.common:log_it:554 - Finished call to 'MCTS.Lingma.ask_llm_location_file.ChatGPT.get_reward' after 67.803(s), this was the 2nd time calling it. exp: ('Connection aborted.', RemoteDisconnected('Remote end closed connection without response'))
2024-05-15 23:17:58.591 | ERROR    | metagpt.utils.common:log_it:554 - Finished call to 'MCTS.Lingma.ask_llm_location_file.ChatGPT.get_reward' after 72.717(s), this was the 1st time calling it. exp: ('Connection aborted.', RemoteDisconnected('Remote end closed connection without response'))
2024-05-15 23:20:26.873 | ERROR    | metagpt.utils.common:log_it:554 - Finished call to 'MCTS.Lingma.ask_llm_location_file.ChatGPT.get_reward' after 1.183(s), this was the 1st time calling it. exp: 请求失败。
Message: {"code":200,"data":"{\"error\":{\"code\":\"DeploymentNotFound\", \"message\":\"The API deployment for this resource does not exist. If you created the deployment within the last 5 minutes, please wait a moment and try again.\"}}","message":"success"}

2024-05-15 23:20:35.983 | ERROR    | metagpt.utils.common:log_it:554 - Finished call to 'MCTS.Lingma.ask_llm_location_file.ChatGPT.get_reward' after 10.293(s), this was the 2nd time calling it. exp: 请求失败。
Message: {"code":200,"data":"{\"error\":{\"code\":\"DeploymentNotFound\", \"message\":\"The API deployment for this resource does not exist. If you created the deployment within the last 5 minutes, please wait a moment and try again.\"}}","message":"success"}

2024-05-15 23:33:16.210 | ERROR    | metagpt.utils.common:log_it:554 - Finished call to 'MCTS.Lingma.ask_llm_location_file.ChatGPT.get_reward' after 0.935(s), this was the 1st time calling it. exp: 请求失败。
Message: {"code":200,"data":"{\"error\":{\"code\":\"DeploymentNotFound\", \"message\":\"The API deployment for this resource does not exist. If you created the deployment within the last 5 minutes, please wait a moment and try again.\"}}","message":"success"}

2024-05-15 23:33:16.211 | ERROR    | metagpt.utils.common:log_it:554 - Finished call to 'MCTS.Lingma.ask_llm_location_file.ChatGPT.get_reward' after 0.936(s), this was the 1st time calling it. exp: 请求失败。
Message: {"code":200,"data":"{\"error\":{\"code\":\"DeploymentNotFound\", \"message\":\"The API deployment for this resource does not exist. If you created the deployment within the last 5 minutes, please wait a moment and try again.\"}}","message":"success"}

2024-05-15 23:42:16.787 | ERROR    | metagpt.utils.common:log_it:554 - Finished call to 'MCTS.Lingma.ask_llm_location_file.ChatGPT.chat' after 1.555(s), this was the 1st time calling it. exp: 请求失败。
Message: {"code":200,"data":"{\"error\":{\"code\":\"DeploymentNotFound\", \"message\":\"The API deployment for this resource does not exist. If you created the deployment within the last 5 minutes, please wait a moment and try again.\"}}","message":"success"}

2024-05-16 00:04:08.294 | ERROR    | metagpt.utils.common:log_it:554 - Finished call to 'MCTS.Lingma.ask_llm_location_file.ChatGPT.ask_summary_results' after 0.640(s), this was the 1st time calling it. exp: 请求失败。
Message: {"code":200,"data":"{\"error\":{\"code\":\"DeploymentNotFound\", \"message\":\"The API deployment for this resource does not exist. If you created the deployment within the last 5 minutes, please wait a moment and try again.\"}}","message":"success"}

2024-05-16 00:07:03.084 | ERROR    | metagpt.utils.common:log_it:554 - Finished call to 'MCTS.Lingma.ask_llm_location_file.ChatGPT.chat' after 1.437(s), this was the 1st time calling it. exp: 请求失败。
Message: {"code":200,"data":"{\"error\":{\"code\":\"DeploymentNotFound\", \"message\":\"The API deployment for this resource does not exist. If you created the deployment within the last 5 minutes, please wait a moment and try again.\"}}","message":"success"}

2024-05-16 00:10:45.803 | ERROR    | metagpt.utils.common:log_it:554 - Finished call to 'MCTS.Lingma.ask_llm_location_file.ChatGPT.get_reward' after 1.076(s), this was the 1st time calling it. exp: 请求失败。
Message: {"code":200,"data":"{\"error\":{\"code\":\"DeploymentNotFound\", \"message\":\"The API deployment for this resource does not exist. If you created the deployment within the last 5 minutes, please wait a moment and try again.\"}}","message":"success"}

2024-05-16 00:10:45.805 | ERROR    | metagpt.utils.common:log_it:554 - Finished call to 'MCTS.Lingma.ask_llm_location_file.ChatGPT.get_reward' after 1.085(s), this was the 1st time calling it. exp: 请求失败。
Message: {"code":200,"data":"{\"error\":{\"code\":\"DeploymentNotFound\", \"message\":\"The API deployment for this resource does not exist. If you created the deployment within the last 5 minutes, please wait a moment and try again.\"}}","message":"success"}

2024-05-16 00:10:48.721 | ERROR    | metagpt.utils.common:log_it:554 - Finished call to 'MCTS.Lingma.ask_llm_location_file.ChatGPT.get_reward' after 3.993(s), this was the 2nd time calling it. exp: 请求失败。
Message: {"code":200,"data":"{\"error\":{\"code\":\"DeploymentNotFound\", \"message\":\"The API deployment for this resource does not exist. If you created the deployment within the last 5 minutes, please wait a moment and try again.\"}}","message":"success"}

2024-05-16 00:10:57.784 | ERROR    | metagpt.utils.common:log_it:554 - Finished call to 'MCTS.Lingma.ask_llm_location_file.ChatGPT.get_reward' after 13.057(s), this was the 3rd time calling it. exp: 请求失败。
Message: {"code":200,"data":"{\"error\":{\"code\":\"DeploymentNotFound\", \"message\":\"The API deployment for this resource does not exist. If you created the deployment within the last 5 minutes, please wait a moment and try again.\"}}","message":"success"}

2024-05-16 00:11:06.720 | ERROR    | metagpt.utils.common:log_it:554 - Finished call to 'MCTS.Lingma.ask_llm_location_file.ChatGPT.get_reward' after 21.993(s), this was the 4th time calling it. exp: 请求失败。
Message: {"code":200,"data":"{\"error\":{\"code\":\"DeploymentNotFound\", \"message\":\"The API deployment for this resource does not exist. If you created the deployment within the last 5 minutes, please wait a moment and try again.\"}}","message":"success"}

2024-05-16 00:12:01.702 | ERROR    | metagpt.utils.common:log_it:554 - Finished call to 'MCTS.Lingma.ask_llm_location_file.ChatGPT.get_reward' after 0.755(s), this was the 1st time calling it. exp: 请求失败。
Message: {"code":200,"data":"{\"error\":{\"code\":\"DeploymentNotFound\", \"message\":\"The API deployment for this resource does not exist. If you created the deployment within the last 5 minutes, please wait a moment and try again.\"}}","message":"success"}

2024-05-16 00:13:12.355 | ERROR    | metagpt.utils.common:log_it:554 - Finished call to 'MCTS.Lingma.ask_llm_location_file.ChatGPT.get_reward' after 0.963(s), this was the 1st time calling it. exp: 请求失败。
Message: {"code":200,"data":"{\"error\":{\"code\":\"DeploymentNotFound\", \"message\":\"The API deployment for this resource does not exist. If you created the deployment within the last 5 minutes, please wait a moment and try again.\"}}","message":"success"}

2024-05-16 00:13:12.782 | ERROR    | metagpt.utils.common:log_it:554 - Finished call to 'MCTS.Lingma.ask_llm_location_file.ChatGPT.get_reward' after 1.386(s), this was the 1st time calling it. exp: 请求失败。
Message: {"code":200,"data":"{\"error\":{\"code\":\"DeploymentNotFound\", \"message\":\"The API deployment for this resource does not exist. If you created the deployment within the last 5 minutes, please wait a moment and try again.\"}}","message":"success"}

2024-05-16 00:13:12.796 | ERROR    | metagpt.utils.common:log_it:554 - Finished call to 'MCTS.Lingma.ask_llm_location_file.ChatGPT.get_reward' after 1.400(s), this was the 1st time calling it. exp: 请求失败。
Message: {"code":200,"data":"{\"error\":{\"code\":\"DeploymentNotFound\", \"message\":\"The API deployment for this resource does not exist. If you created the deployment within the last 5 minutes, please wait a moment and try again.\"}}","message":"success"}

2024-05-16 00:13:14.398 | ERROR    | metagpt.utils.common:log_it:554 - Finished call to 'MCTS.Lingma.ask_llm_location_file.ChatGPT.get_reward' after 3.006(s), this was the 2nd time calling it. exp: 请求失败。
Message: {"code":200,"data":"{\"error\":{\"code\":\"DeploymentNotFound\", \"message\":\"The API deployment for this resource does not exist. If you created the deployment within the last 5 minutes, please wait a moment and try again.\"}}","message":"success"}

2024-05-16 00:13:21.245 | ERROR    | metagpt.utils.common:log_it:554 - Finished call to 'MCTS.Lingma.ask_llm_location_file.ChatGPT.get_reward' after 9.853(s), this was the 3rd time calling it. exp: 请求失败。
Message: {"code":200,"data":"{\"error\":{\"code\":\"DeploymentNotFound\", \"message\":\"The API deployment for this resource does not exist. If you created the deployment within the last 5 minutes, please wait a moment and try again.\"}}","message":"success"}

