2024-05-19 11:36:59.529 | ERROR    | metagpt.utils.common:log_it:554 - Finished call to 'MCTS.Lingma.ask_llm_location_file.ChatGPT.get_reward' after 1.968(s), this was the 1st time calling it. exp: no score found for The provided code
2024-05-19 12:12:31.325 | ERROR    | metagpt.utils.common:log_it:554 - Finished call to 'MCTS.Lingma.ask_llm_location_file.ChatGPT.get_reward' after 301.844(s), this was the 1st time calling it. exp: 请求失败。
Message: {"code":500,"message":"服务器异常:('Connection broken: IncompleteRead(0 bytes read)', IncompleteRead(0 bytes read))"}

2024-05-19 12:12:52.423 | ERROR    | metagpt.utils.common:log_it:554 - Finished call to 'MCTS.Lingma.ask_llm_location_file.ChatGPT.get_reward' after 10.664(s), this was the 1st time calling it. exp: no score found for The provided `DATAARRAY_NAME` from `xarray/backends/api.py` is simply a string constant definition and bears no direct functionality that would cause a dask DataArray to evaluate its values eagerly or affect its chunking when using `DataSet.update`. This constant seems to be used for identification purposes within xarray's backend, and not for the control of DataArray evaluation or dataset manipulation which are described in the issue.

The issue reports a behavior in xarray where updating a chunked dask DataArray within an `xr.Dataset` results in the DataArray losing its chunking. This unexpected behavior would indeed indicate a problem, but the problem would likely lie within the implementation of the `update` method or chunk handling within datasets, rather than with a constant that is used to name DataArrays within the backend system.

Considering the context, the issue seems related to xarray's dataset and dataarray handling features possibly within methods like `update()`, constructors, or other parts of the code that handle chunking and data manipulation.

As the constant `DATAARRAY_NAME` has no functional relation with the `update` method or dataset management logic, it is improbable that modifying this constant would resolve the issue described. The appropriate area to look into would likely be the implementation of the `update` method or around the underlying chunk management in datasets and the interactions with dask arrays.

Result: Thus the probability score that this code needs to be modified to solve this issue is a 1.
2024-05-19 13:13:23.129 | ERROR    | metagpt.utils.common:log_it:554 - Finished call to 'MCTS.Lingma.ask_llm_location_file.ChatGPT.get_reward' after 11.625(s), this was the 1st time calling it. exp: no score found for The issue describes a problem that occurs when using `ExpressionWrapper` in combination with negating a `Q` object that contains an empty list (`pk__in=[]`). According to the description, the query works fine when it's not negated, resulting in the query `SELECT 0 AS "foo" FROM "table"`. However, when negation is introduced by using `~Q(pk__in=[])`, the query breaks and produces invalid SQL.

The provided code snippet is a method from the `ExpressionWrapper` class in Django's ORM framework, but it only shows a method that returns a list of source expressions, without revealing how these expressions are processed and incorporated into the SQL query. This might not be the method where the issue stems from, as we would need to inspect the logic by which expressions are converted into SQL syntax. The root of the problem might be in the mechanisms of the Django ORM that handle the translation from Q-objects to SQL, especially how negation (`~`) is handled when applied to empty lookups.

Without seeing the code that processes and translates the `ExpressionWrapper` and `Q` objects into SQL queries, it's challenging to provide a precise diagnosis. However, given the nature of the problem, it is likely that the code responsible for query generation – where expression objects are turned into the corresponding SQL representation – needs to be examined and potentially fixed to handle the negation of empty Q objects correctly.

Result: Thus the probability score that this code needs to be modified to solve this issue is around 4, considering this specific `get_source_expressions` method might not be where the problem lies, but the broader system that translates the `ExpressionWrapper` expressions into SQL does seem to have a bug that needs addressing.
2024-05-19 13:24:54.523 | ERROR    | metagpt.utils.common:log_it:554 - Finished call to 'MCTS.Lingma.ask_llm_location_file.ChatGPT.get_reward' after 14.120(s), this was the 1st time calling it. exp: no score found for The issue reports inconsistencies between the LaTeX printer and the pretty printer in the SymPy library. Specifically, the LaTeX printer is generating different output compared to the pretty printer for the same expressions. In particular, the example given involves the rendering of expressions involving exponential, logarithms, and fractions. This indicates discrepancies in the printing mechanism for LaTeX output versus pretty-print output.

The code provided is for the `pretty_print` function from the `sympy/printing/pretty/pretty.py` file, which is used to print expressions in a "pretty" form (i.e., as they would appear in a textbook), typically displayed in the console.

The issue is specifically with the LaTeX printer, and while the code provided is for the pretty printer, it's part of the same overall printing system in SymPy. Due to the nature of pretty printing focusing on console output and LaTeX printer targeting LaTeX formatting, we should not anticipate direct unity between the two, but they should symbolically represent the same mathematical meaning. However, according to the issue, if the assumptions do not affect the pretty printing, they should not affect the LaTeX printing either, and the discrepancy should be resolved.

To fix the issue, it's likely that the LaTeX printing module in SymPy has to be examined and potentially modified for consistency. Therefore, the alteration should happen in the LaTeX printing functionality, which might be in files like `sympy/printing/latex.py` or similar, not in the pretty printing code that is provided here.

The function `pretty_print` itself does not seem to be the cause of the LaTeX inconsistencies. Instead, one should inspect the LaTeX-generating functions or methods for the bug.

In conclusion, the provided `pretty_print` function does not appear to be directly responsible for the issue at hand. Thus, the probability score that this code needs to be modified to solve this issue is likely low. However, the exact score would depend on the interdependence of the pretty and LaTeX printing mechanisms within SymPy, which is not fully detailed here.

Result: Thus the probability score that this code needs to be modified to solve this issue is likely 2, assuming the LaTeX printer has its separate implementation that does not rely on the provided pretty print code.
2024-05-19 14:19:30.764 | ERROR    | metagpt.utils.common:log_it:554 - Finished call to 'MCTS.Lingma.ask_llm_location_file.ChatGPT.get_reward' after 11.251(s), this was the 1st time calling it. exp: no score found for The code provided is related to the `Memory` class's `eval` method in the `sklearn/externals/joblib/memory.py` file. This method is used for caching the result of a function, such that if the function with the same arguments is called again, the cached result is returned instead of re-evaluating the function.

The issue described pertains to the `LabelEncoder` class in scikit-learn, specifically the `transform` method's handling of empty lists. The error occurs when an empty list is passed to the `transform` method after fitting the encoder with string values. There is a type mismatch that raises a `TypeError` because NumPy is unable to cast the array data safely from one data type to another.

The submitted code mentions the `eval` method from the `joblib` library used for caching, which does not seem to be directly related to the issue with `LabelEncoder`'s `transform` method. The problem with `LabelEncoder` is more likely related to the scikit-learn's `LabelEncoder` class and not the caching mechanism of `joblib`.

Based on this reasoning, the probability that the provided `Memory` class `eval` function in the `sklearn/externals/joblib/memory.py` file needs to be modified to solve the reported issue with `LabelEncoder` is extremely low. Modifications are needed in the `LabelEncoder` class, particularly in how it handles transformations of empty lists and data type casting internally.

Thus the probability score that this code needs to be modified to solve this issue is `1`.
2024-05-19 14:46:18.955 | ERROR    | metagpt.utils.common:log_it:554 - Finished call to 'MCTS.Lingma.ask_llm_location_file.ChatGPT.get_reward' after 18.366(s), this was the 1st time calling it. exp: no score found for There's not enough code provided in the snippet given to determine if the mentioned bug about the Python 2 to 3 pickling issue with sympy expressions is within the scope of `sympy/core/numbers.py`. The issue described is with loading a pickled sympy expression that contains a float, which generates an error due to a syntactic change in how integers are expressed in Python 3 (e.g., removing the 'L' suffix for long integers).

The code snippet provided only shows the definition of a variable `rnd` that is assigned to `mlib.round_nearest` which seems unrelated to serialization and deserialization mechanisms like pickle. Since the traceback in the issue mentions `sympy/core/numbers.py`, line 1045, which is not part of the provided snippet, we cannot confirm if the shown code is the buggy location.

We would need to examine the actual `__new__` method of the class where the error is raised, as indicated by the traceback provided in the issue description. The error seems to happen when the integer representation of a number is attempted, but with an invalid literal for the int constructor (an artifact of Python 2 style long integer representation).

However, based on the error message and the line mentioned in the traceback, it is likely that the compatibility problem arises from handling Python 2 long integers (`1L`) in Python 3, where the syntax for long integers has changed and the 'L' suffix has been dropped. The code that handles parsing or interpreting these literals would need to be updated to ensure compatibility between Python 2 and Python 3 pickle serialization.

Given the available information and the nature of the issue described:

Result: Thus the probability score that this code needs to be modified to solve this issue is unknown, given the provided code, but if we assume that the description in the issue about `sympy/core/numbers.py` is where the error lies, the probability score that `numbers.py` (particularly around line 1045) needs to be modified to resolve the issue would be high, likely a 9 or 10.
2024-05-19 15:39:08.460 | ERROR    | metagpt.utils.common:log_it:554 - Finished call to 'MCTS.Lingma.ask_llm_location_file.ChatGPT.get_reward' after 11.913(s), this was the 1st time calling it. exp: no score found for It seems the provided information is incomplete; the thought process for the last issue around "Support for serialization of combination of Enum flags" is not finished, and the associated code snippet is unrelated to the issue. The `__call__` method from a `BadSerializer` class in Django doesn't provide enough context or relevance to the issue of serializing a combination of Enum flags.

The issue is describing a situation where the serialization process is not accounting for IntegerField values that are combinations of Enum flags, which should be heeded to support sensible defaults in model migrations. This feature would likely involve inspecting and adapting the serialization logic to correctly handle the combination of Enum flags, possibly in the part of the Django codebase that deals with migrations and field serialization.

However, without seeing the relevant parts of the Django codebase that handle IntegerField serialization and migration generation, it's impossible to definitively determine if the `__call__` method in the `BadSerializer` class is a cause of the described issue or whether it needs to be modified. 

Based on the information provided, we need to review and potentially modify the serialization logic within the Django migrations framework that handles the enumeration of integer-based flags. But since the exact code responsible for serialization and migration of Enum flags is not provided, we cannot assign an accurate probability score for the modification of the `__call__` method in the `BadSerializer` class to resolve the stated issue.

Result: Thus the probability score that this code needs to be modified to solve this issue is uncertain based on the current context provided. More relevant code or context would be needed to offer a definitive probability score.
2024-05-19 15:44:40.598 | ERROR    | metagpt.utils.common:log_it:554 - Finished call to 'MCTS.Lingma.ask_llm_location_file.ChatGPT.get_reward' after 1.913(s), this was the 1st time calling it. exp: no score found for The issue described involves the
2024-05-19 16:07:25.311 | ERROR    | metagpt.utils.common:log_it:554 - Finished call to 'MCTS.Lingma.ask_llm_location_file.ChatGPT.get_reward' after 2.252(s), this was the 1st time calling it. exp: 请求失败。
Message: {"code":500,"message":"服务器异常:'NoneType' object is not iterable"}

2024-05-19 16:22:20.854 | ERROR    | metagpt.utils.common:log_it:554 - Finished call to 'MCTS.Lingma.ask_llm_location_file.ChatGPT.get_reward' after 1.495(s), this was the 1st time calling it. exp: 请求失败。
Message: {"code":200,"data":"{\"timestamp\":\"2024-05-19T08:22:20.775+00:00\",\"status\":500,\"error\":\"Internal Server Error\",\"path\":\"/proxy/v1/chat/completions\"}","message":"success"}

2024-05-19 16:22:32.080 | ERROR    | metagpt.utils.common:log_it:554 - Finished call to 'MCTS.Lingma.ask_llm_location_file.ChatGPT.get_reward' after 1.588(s), this was the 1st time calling it. exp: 请求失败。
Message: {"code":200,"data":"{\"timestamp\":\"2024-05-19T08:22:31.262+00:00\",\"status\":500,\"error\":\"Internal Server Error\",\"path\":\"/proxy/v1/chat/completions\"}","message":"success"}

2024-05-19 16:22:46.760 | ERROR    | metagpt.utils.common:log_it:554 - Finished call to 'MCTS.Lingma.ask_llm_location_file.ChatGPT.get_reward' after 0.937(s), this was the 1st time calling it. exp: 请求失败。
Message: {"code":200,"data":"{\"timestamp\":\"2024-05-19T08:22:46.682+00:00\",\"status\":500,\"error\":\"Internal Server Error\",\"path\":\"/proxy/v1/chat/completions\"}","message":"success"}

2024-05-19 16:23:26.534 | ERROR    | metagpt.utils.common:log_it:554 - Finished call to 'MCTS.Lingma.ask_llm_location_file.ChatGPT.ask_summary_results' after 0.738(s), this was the 1st time calling it. exp: 请求失败。
Message: {"code":200,"data":"{\"timestamp\":\"2024-05-19T08:23:26.455+00:00\",\"status\":500,\"error\":\"Internal Server Error\",\"path\":\"/proxy/v1/chat/completions\"}","message":"success"}

2024-05-19 17:36:30.810 | ERROR    | metagpt.utils.common:log_it:554 - Finished call to 'MCTS.Lingma.ask_llm_location_file.ChatGPT.get_reward' after 1.683(s), this was the 1st time calling it. exp: no score found for The code provided is part
2024-05-19 17:36:50.901 | ERROR    | metagpt.utils.common:log_it:554 - Finished call to 'MCTS.Lingma.ask_llm_location_file.ChatGPT.get_reward' after 0.951(s), this was the 1st time calling it. exp: 请求失败。
Message: {"code":200,"data":"{\"timestamp\":\"2024-05-19T09:36:50.776+00:00\",\"status\":500,\"error\":\"Internal Server Error\",\"path\":\"/proxy/v1/chat/completions\"}","message":"success"}

2024-05-19 17:36:52.387 | ERROR    | metagpt.utils.common:log_it:554 - Finished call to 'MCTS.Lingma.ask_llm_location_file.ChatGPT.get_reward' after 0.955(s), this was the 1st time calling it. exp: 请求失败。
Message: {"code":200,"data":"{\"timestamp\":\"2024-05-19T09:36:52.243+00:00\",\"status\":500,\"error\":\"Internal Server Error\",\"path\":\"/proxy/v1/chat/completions\"}","message":"success"}

2024-05-19 17:37:12.035 | ERROR    | metagpt.utils.common:log_it:554 - Finished call to 'MCTS.Lingma.ask_llm_location_file.ChatGPT.get_reward' after 0.959(s), this was the 1st time calling it. exp: 请求失败。
Message: {"code":200,"data":"{\"timestamp\":\"2024-05-19T09:37:11.907+00:00\",\"status\":500,\"error\":\"Internal Server Error\",\"path\":\"/proxy/v1/chat/completions\"}","message":"success"}

2024-05-19 17:37:13.096 | ERROR    | metagpt.utils.common:log_it:554 - Finished call to 'MCTS.Lingma.ask_llm_location_file.ChatGPT.get_reward' after 2.022(s), this was the 1st time calling it. exp: 请求失败。
Message: {"code":200,"data":"{\"timestamp\":\"2024-05-19T09:37:12.746+00:00\",\"status\":500,\"error\":\"Internal Server Error\",\"path\":\"/proxy/v1/chat/completions\"}","message":"success"}

2024-05-19 17:37:13.529 | ERROR    | metagpt.utils.common:log_it:554 - Finished call to 'MCTS.Lingma.ask_llm_location_file.ChatGPT.get_reward' after 1.455(s), this was the 1st time calling it. exp: 请求失败。
Message: {"code":200,"data":"{\"timestamp\":\"2024-05-19T09:37:12.731+00:00\",\"status\":500,\"error\":\"Internal Server Error\",\"path\":\"/proxy/v1/chat/completions\"}","message":"success"}

2024-05-19 17:37:14.364 | ERROR    | metagpt.utils.common:log_it:554 - Finished call to 'MCTS.Lingma.ask_llm_location_file.ChatGPT.get_reward' after 2.291(s), this was the 1st time calling it. exp: no score found for The provided issue describes a
2024-05-19 17:37:15.147 | ERROR    | metagpt.utils.common:log_it:554 - Finished call to 'MCTS.Lingma.ask_llm_location_file.ChatGPT.get_reward' after 0.957(s), this was the 1st time calling it. exp: 请求失败。
Message: {"code":200,"data":"{\"timestamp\":\"2024-05-19T09:37:15.020+00:00\",\"status\":500,\"error\":\"Internal Server Error\",\"path\":\"/proxy/v1/chat/completions\"}","message":"success"}

2024-05-19 17:37:39.325 | ERROR    | metagpt.utils.common:log_it:554 - Finished call to 'MCTS.Lingma.ask_llm_location_file.ChatGPT.get_reward' after 0.778(s), this was the 1st time calling it. exp: 请求失败。
Message: {"code":200,"data":"{\"timestamp\":\"2024-05-19T09:37:39.175+00:00\",\"status\":500,\"error\":\"Internal Server Error\",\"path\":\"/proxy/v1/chat/completions\"}","message":"success"}

2024-05-19 17:37:45.694 | ERROR    | metagpt.utils.common:log_it:554 - Finished call to 'MCTS.Lingma.ask_llm_location_file.ChatGPT.get_reward' after 1.953(s), this was the 1st time calling it. exp: no score found for The provided code is from
2024-05-19 17:37:46.571 | ERROR    | metagpt.utils.common:log_it:554 - Finished call to 'MCTS.Lingma.ask_llm_location_file.ChatGPT.get_reward' after 2.831(s), this was the 1st time calling it. exp: 请求失败。
Message: {"code":200,"data":"{\"timestamp\":\"2024-05-19T09:37:46.435+00:00\",\"status\":500,\"error\":\"Internal Server Error\",\"path\":\"/proxy/v1/chat/completions\"}","message":"success"}

2024-05-19 17:38:01.171 | ERROR    | metagpt.utils.common:log_it:554 - Finished call to 'MCTS.Lingma.ask_llm_location_file.ChatGPT.get_reward' after 0.760(s), this was the 1st time calling it. exp: 请求失败。
Message: {"code":200,"data":"{\"timestamp\":\"2024-05-19T09:38:01.035+00:00\",\"status\":500,\"error\":\"Internal Server Error\",\"path\":\"/proxy/v1/chat/completions\"}","message":"success"}

2024-05-19 17:53:40.578 | ERROR    | metagpt.utils.common:log_it:554 - Finished call to 'MCTS.Lingma.ask_llm_location_file.ChatGPT.get_reward' after 2.104(s), this was the 1st time calling it. exp: no score found for The issue describes a feature
2024-05-19 17:54:01.453 | ERROR    | metagpt.utils.common:log_it:554 - Finished call to 'MCTS.Lingma.ask_llm_location_file.ChatGPT.get_reward' after 0.729(s), this was the 1st time calling it. exp: 请求失败。
Message: {"code":200,"data":"{\"timestamp\":\"2024-05-19T09:54:01.289+00:00\",\"status\":500,\"error\":\"Internal Server Error\",\"path\":\"/proxy/v1/chat/completions\"}","message":"success"}

2024-05-19 17:54:03.701 | ERROR    | metagpt.utils.common:log_it:554 - Finished call to 'MCTS.Lingma.ask_llm_location_file.ChatGPT.get_reward' after 2.992(s), this was the 1st time calling it. exp: no score found for The provided issue discusses a
2024-05-19 17:54:17.216 | ERROR    | metagpt.utils.common:log_it:554 - Finished call to 'MCTS.Lingma.ask_llm_location_file.ChatGPT.get_reward' after 0.781(s), this was the 1st time calling it. exp: 请求失败。
Message: {"code":200,"data":"{\"timestamp\":\"2024-05-19T09:54:17.054+00:00\",\"status\":500,\"error\":\"Internal Server Error\",\"path\":\"/proxy/v1/chat/completions\"}","message":"success"}

2024-05-19 17:54:17.676 | ERROR    | metagpt.utils.common:log_it:554 - Finished call to 'MCTS.Lingma.ask_llm_location_file.ChatGPT.get_reward' after 1.241(s), this was the 1st time calling it. exp: 请求失败。
Message: {"code":200,"data":"{\"timestamp\":\"2024-05-19T09:54:17.493+00:00\",\"status\":500,\"error\":\"Internal Server Error\",\"path\":\"/proxy/v1/chat/completions\"}","message":"success"}

2024-05-19 17:54:19.291 | ERROR    | metagpt.utils.common:log_it:554 - Finished call to 'MCTS.Lingma.ask_llm_location_file.ChatGPT.get_reward' after 2.854(s), this was the 1st time calling it. exp: no score found for The issue describes a feature
2024-05-19 17:54:37.725 | ERROR    | metagpt.utils.common:log_it:554 - Finished call to 'MCTS.Lingma.ask_llm_location_file.ChatGPT.get_reward' after 0.763(s), this was the 1st time calling it. exp: 请求失败。
Message: {"code":200,"data":"{\"timestamp\":\"2024-05-19T09:54:37.555+00:00\",\"status\":500,\"error\":\"Internal Server Error\",\"path\":\"/proxy/v1/chat/completions\"}","message":"success"}

2024-05-19 17:54:57.788 | ERROR    | metagpt.utils.common:log_it:554 - Finished call to 'MCTS.Lingma.ask_llm_location_file.ChatGPT.get_reward' after 1.085(s), this was the 1st time calling it. exp: 请求失败。
Message: {"code":200,"data":"{\"timestamp\":\"2024-05-19T09:54:57.616+00:00\",\"status\":500,\"error\":\"Internal Server Error\",\"path\":\"/proxy/v1/chat/completions\"}","message":"success"}

2024-05-19 17:54:58.690 | ERROR    | metagpt.utils.common:log_it:554 - Finished call to 'MCTS.Lingma.ask_llm_location_file.ChatGPT.get_reward' after 1.987(s), this was the 1st time calling it. exp: no score found for The code provided is the
2024-05-19 17:55:00.586 | ERROR    | metagpt.utils.common:log_it:554 - Finished call to 'MCTS.Lingma.ask_llm_location_file.ChatGPT.get_reward' after 2.370(s), this was the 1st time calling it. exp: no score found for The issue suggests
2024-05-19 18:24:00.461 | ERROR    | metagpt.utils.common:log_it:554 - Finished call to 'MCTS.Lingma.ask_llm_location_file.ChatGPT.get_reward' after 2.111(s), this was the 1st time calling it. exp: no score found for The issued presented is not
2024-05-19 18:25:33.628 | ERROR    | metagpt.utils.common:log_it:554 - Finished call to 'MCTS.Lingma.ask_llm_location_file.ChatGPT.get_reward' after 1.835(s), this was the 1st time calling it. exp: no score found for The issue requests
2024-05-19 18:29:44.136 | ERROR    | metagpt.utils.common:log_it:554 - Finished call to 'MCTS.Lingma.ask_llm_location_file.ChatGPT.get_reward' after 3.392(s), this was the 1st time calling it. exp: no score found for The provided issue discusses an unexpected behavior in Django where fields of an abstract model, when inherited by concrete models, are considered equal due to their comparison being based only on their `creation_counter`. The reported problem suggests that the field comparison mechanism should take into account the models of the fields bei
2024-05-19 18:32:22.476 | ERROR    | metagpt.utils.common:log_it:554 - Finished call to 'MCTS.Lingma.ask_llm_location_file.ChatGPT.get_reward' after 2.377(s), this was the 1st time calling it. exp: no score found for The issue describes an inconsistency
2024-05-19 19:44:04.820 | ERROR    | metagpt.utils.common:log_it:554 - Finished call to 'MCTS.Lingma.ask_llm_location_file.ChatGPT.get_reward' after 2.027(s), this was the 1st time calling it. exp: no score found for The
2024-05-19 20:27:54.290 | ERROR    | metagpt.utils.common:log_it:554 - Finished call to 'MCTS.Lingma.ask_llm_location_file.ChatGPT.get_reward' after 22.027(s), this was the 1st time calling it. exp: 请求失败。
Message: {"code":200,"data":"{\"timestamp\":\"2024-05-19T12:27:54.308+00:00\",\"status\":500,\"error\":\"Internal Server Error\",\"path\":\"/proxy/v1/chat/completions\"}","message":"success"}

2024-05-19 20:38:41.220 | ERROR    | metagpt.utils.common:log_it:554 - Finished call to 'MCTS.Lingma.ask_llm_location_file.ChatGPT.get_reward' after 14.030(s), this was the 1st time calling it. exp: no score found for The issue is specifically about the `evaluate(False)` context manager crashing when used with `Point2D` in the Sympy library. The error indicates that when `evaluate(False)` is used, the program is unexpectedly encountering imaginary coordinates, which are not permitted—although, in reality, the coordinates provided are not imaginary.

The presented code snippet does not show the actual execution of the creation of a `Point2D` object nor the handling of the `evaluate` context in Sympy:

```python
# class method ParenthesisGroup in sympy/parsing/sympy_parser.py file
class ParenthesisGroup(list):
    """List of tokens representing an expression in parentheses."""
    pass
```

The `ParenthesisGroup` class is a part of the internal parsing mechanics of Sympy but not directly related to the evaluation context or the construction of a `Point2D` object.

The underlying issue might be related to the `sympify` process within the `evaluate` context that is failing to properly construct a `Point2D` object or an error in the `evaluate` context manager itself. However, because the actual involved code (such as the `evaluate` context manager or the implementation of `Point2D`) is not provided, we cannot be certain of the exact code block that requires modification to resolve this specific issue.

Based on the given information and the nature of the problem described in the issue, it is highly likely that the problem lies deep within the logic that handles the `evaluate` context or within the constructors and sympification processes for geometric entities.

To actually address the issue, developers would need to inspect the handling of `evaluate(False)` within the context of object construction in the geometry module, or the code responsible for sympification of such objects. Without the exact code responsible for the issue being presented, it is not possible to give an accurate probability score.

Result: Thus the probability score that this code needs to be modified to solve this issue is undeterminable from the given information.
2024-05-19 20:39:41.268 | ERROR    | metagpt.utils.common:log_it:554 - Finished call to 'MCTS.Lingma.ask_llm_location_file.ChatGPT.get_reward' after 9.670(s), this was the 1st time calling it. exp: ('Connection aborted.', RemoteDisconnected('Remote end closed connection without response'))
2024-05-19 20:39:41.290 | ERROR    | metagpt.utils.common:log_it:554 - Finished call to 'MCTS.Lingma.ask_llm_location_file.ChatGPT.get_reward' after 9.490(s), this was the 1st time calling it. exp: ('Connection aborted.', RemoteDisconnected('Remote end closed connection without response'))
2024-05-19 20:39:41.322 | ERROR    | metagpt.utils.common:log_it:554 - Finished call to 'MCTS.Lingma.ask_llm_location_file.ChatGPT.get_reward' after 9.724(s), this was the 1st time calling it. exp: ('Connection aborted.', RemoteDisconnected('Remote end closed connection without response'))
2024-05-19 20:39:41.506 | ERROR    | metagpt.utils.common:log_it:554 - Finished call to 'MCTS.Lingma.ask_llm_location_file.ChatGPT.get_reward' after 9.911(s), this was the 1st time calling it. exp: ('Connection aborted.', RemoteDisconnected('Remote end closed connection without response'))
2024-05-19 20:39:41.633 | ERROR    | metagpt.utils.common:log_it:554 - Finished call to 'MCTS.Lingma.ask_llm_location_file.ChatGPT.get_reward' after 10.037(s), this was the 1st time calling it. exp: ('Connection aborted.', RemoteDisconnected('Remote end closed connection without response'))
2024-05-19 20:39:42.116 | ERROR    | metagpt.utils.common:log_it:554 - Finished call to 'MCTS.Lingma.ask_llm_location_file.ChatGPT.get_reward' after 10.320(s), this was the 1st time calling it. exp: ('Connection aborted.', RemoteDisconnected('Remote end closed connection without response'))
2024-05-19 20:39:42.155 | ERROR    | metagpt.utils.common:log_it:554 - Finished call to 'MCTS.Lingma.ask_llm_location_file.ChatGPT.get_reward' after 10.353(s), this was the 1st time calling it. exp: ('Connection aborted.', RemoteDisconnected('Remote end closed connection without response'))
2024-05-19 20:39:42.322 | ERROR    | metagpt.utils.common:log_it:554 - Finished call to 'MCTS.Lingma.ask_llm_location_file.ChatGPT.get_reward' after 10.724(s), this was the 1st time calling it. exp: ('Connection aborted.', RemoteDisconnected('Remote end closed connection without response'))
2024-05-19 20:39:42.440 | ERROR    | metagpt.utils.common:log_it:554 - Finished call to 'MCTS.Lingma.ask_llm_location_file.ChatGPT.get_reward' after 10.645(s), this was the 1st time calling it. exp: ('Connection aborted.', RemoteDisconnected('Remote end closed connection without response'))
2024-05-19 20:39:42.525 | ERROR    | metagpt.utils.common:log_it:554 - Finished call to 'MCTS.Lingma.ask_llm_location_file.ChatGPT.get_reward' after 10.931(s), this was the 1st time calling it. exp: ('Connection aborted.', RemoteDisconnected('Remote end closed connection without response'))
2024-05-19 20:39:42.725 | ERROR    | metagpt.utils.common:log_it:554 - Finished call to 'MCTS.Lingma.ask_llm_location_file.ChatGPT.get_reward' after 10.867(s), this was the 1st time calling it. exp: ('Connection aborted.', RemoteDisconnected('Remote end closed connection without response'))
2024-05-19 20:39:42.743 | ERROR    | metagpt.utils.common:log_it:554 - Finished call to 'MCTS.Lingma.ask_llm_location_file.ChatGPT.get_reward' after 10.906(s), this was the 1st time calling it. exp: ('Connection aborted.', RemoteDisconnected('Remote end closed connection without response'))
2024-05-19 20:39:42.779 | ERROR    | metagpt.utils.common:log_it:554 - Finished call to 'MCTS.Lingma.ask_llm_location_file.ChatGPT.get_reward' after 11.183(s), this was the 1st time calling it. exp: ('Connection aborted.', RemoteDisconnected('Remote end closed connection without response'))
2024-05-19 20:39:43.055 | ERROR    | metagpt.utils.common:log_it:554 - Finished call to 'MCTS.Lingma.ask_llm_location_file.ChatGPT.get_reward' after 11.462(s), this was the 1st time calling it. exp: ('Connection aborted.', RemoteDisconnected('Remote end closed connection without response'))
2024-05-19 20:39:43.184 | ERROR    | metagpt.utils.common:log_it:554 - Finished call to 'MCTS.Lingma.ask_llm_location_file.ChatGPT.get_reward' after 11.362(s), this was the 1st time calling it. exp: ('Connection aborted.', RemoteDisconnected('Remote end closed connection without response'))
2024-05-19 20:39:43.239 | ERROR    | metagpt.utils.common:log_it:554 - Finished call to 'MCTS.Lingma.ask_llm_location_file.ChatGPT.get_reward' after 11.439(s), this was the 1st time calling it. exp: ('Connection aborted.', RemoteDisconnected('Remote end closed connection without response'))
2024-05-19 20:39:43.571 | ERROR    | metagpt.utils.common:log_it:554 - Finished call to 'MCTS.Lingma.ask_llm_location_file.ChatGPT.get_reward' after 11.719(s), this was the 1st time calling it. exp: ('Connection aborted.', RemoteDisconnected('Remote end closed connection without response'))
2024-05-19 20:39:43.802 | ERROR    | metagpt.utils.common:log_it:554 - Finished call to 'MCTS.Lingma.ask_llm_location_file.ChatGPT.get_reward' after 11.940(s), this was the 1st time calling it. exp: ('Connection aborted.', RemoteDisconnected('Remote end closed connection without response'))
2024-05-19 20:42:20.059 | ERROR    | metagpt.utils.common:log_it:554 - Finished call to 'MCTS.Lingma.ask_llm_location_file.ChatGPT.get_reward' after 19.362(s), this was the 1st time calling it. exp: no score found for The provided code snippet consists of only one line and does not give us much context as to where the issue might be occurring. It merely shows a single line initializing a `ColorConverter` object. The issue described talks about deprecation warnings that arise from using the `plt.get_cmap()` function which calls methods inside the `matplotlib/colors.py` module when handling an `np.empty` array with a dtype of `np.uint8`.

From the actual outcome part of the issue, we can see that the warnings are referencing file `colors.py` at lines 730, 731, and 732, which appear to handle some overflow conditions when casting to a `uint8` dtype. In future versions of NumPy, out-of-bound integer conversion will not be allowed, which will break the current functionality.

Since the provided code snippet is not related to the indicated lines in `matplotlib/colors.py`, it is hard to determine whether the single line of code needs to be modified based on the provided snippet alone. We would need to examine the actual lines (730-732) where the warnings are being triggered to assess whether they are the cause of the issue and whether that code needs to be modified.

However, based on the information given in the actual outcome of the issue, it is highly probable that the code around those lines (`matplotlib/colors.py` lines 730-732) does indeed need modification to comply with the upcoming changes in NumPy 1.24. Since the provided code snippet is not relevant to the issue, it cannot be assessed for modification.

Therefore, without reviewing the exact lines of code that cause the deprecation warning, we cannot conclude that the specific line provided (`colorConverter = ColorConverter()`) needs to be modified. It would be speculative to assign a probability score to the snippet without seeing the exact lines of code that correspond to the issue. 

Thus the probability score that this code needs to be modified to solve this issue is indeterminate based on the provided snippet alone. To adjust the score, more context or the correct portion of the code would be needed.
2024-05-20 00:02:01.697 | ERROR    | metagpt.utils.common:log_it:554 - Finished call to 'MCTS.Lingma.ask_llm_location_file.ChatGPT.get_reward' after 33.965(s), this was the 1st time calling it. exp: 请求失败。
Message: {"code":500,"message":"服务器异常:('Connection aborted.', RemoteDisconnected('Remote end closed connection without response'))"}

2024-05-20 00:02:06.502 | ERROR    | metagpt.utils.common:log_it:554 - Finished call to 'MCTS.Lingma.ask_llm_location_file.ChatGPT.get_reward' after 38.773(s), this was the 1st time calling it. exp: 请求失败。
Message: {"code":500,"message":"服务器异常:('Connection aborted.', RemoteDisconnected('Remote end closed connection without response'))"}

2024-05-20 00:02:57.596 | ERROR    | metagpt.utils.common:log_it:554 - Finished call to 'MCTS.Lingma.ask_llm_location_file.ChatGPT.get_reward' after 89.863(s), this was the 1st time calling it. exp: 请求失败。
Message: {"code":200,"data":"<!DOCTYPE HTML PUBLIC \"-//IETF//DTD HTML 2.0//EN\">\r\n<html>\r\n<head><title>502 Bad Gateway</title></head>\r\n<body>\r\n<h1>502 Bad Gateway</h1>\r\n<p>The proxy server received an invalid response from an upstream server.<hr/>Powered by Tengine</body>\r\n</html>\r\n","message":"success"}

2024-05-20 00:06:23.162 | ERROR    | metagpt.utils.common:log_it:554 - Finished call to 'MCTS.Lingma.ask_llm_location_file.ChatGPT.get_reward' after 302.309(s), this was the 1st time calling it. exp: 请求失败。
Message: {"code":500,"message":"服务器异常:('Connection aborted.', ConnectionResetError(104, 'Connection reset by peer'))"}

2024-05-20 01:46:48.032 | ERROR    | metagpt.utils.common:log_it:554 - Finished call to 'MCTS.Lingma.ask_llm_location_file.ChatGPT.get_reward' after 0.733(s), this was the 1st time calling it. exp: 请求失败。
Message: {"code":200,"data":"{\"timestamp\":\"2024-05-19T17:46:47.939+00:00\",\"status\":500,\"error\":\"Internal Server Error\",\"path\":\"/proxy/v1/chat/completions\"}","message":"success"}

2024-05-20 02:14:37.005 | ERROR    | metagpt.utils.common:log_it:554 - Finished call to 'MCTS.Lingma.ask_llm_location_file.ChatGPT.get_reward' after 1.180(s), this was the 1st time calling it. exp: 请求失败。
Message: {"code":200,"data":"{\"timestamp\":\"2024-05-19T18:14:36.749+00:00\",\"status\":500,\"error\":\"Internal Server Error\",\"path\":\"/proxy/v1/chat/completions\"}","message":"success"}

2024-05-20 02:14:37.391 | ERROR    | metagpt.utils.common:log_it:554 - Finished call to 'MCTS.Lingma.ask_llm_location_file.ChatGPT.get_reward' after 1.565(s), this was the 1st time calling it. exp: 请求失败。
Message: {"code":200,"data":"{\"timestamp\":\"2024-05-19T18:14:36.692+00:00\",\"status\":500,\"error\":\"Internal Server Error\",\"path\":\"/proxy/v1/chat/completions\"}","message":"success"}

2024-05-20 02:14:42.659 | ERROR    | metagpt.utils.common:log_it:554 - Finished call to 'MCTS.Lingma.ask_llm_location_file.ChatGPT.get_reward' after 6.834(s), this was the 2nd time calling it. exp: no score found for The issue describes a problem
2024-05-20 02:14:51.702 | ERROR    | metagpt.utils.common:log_it:554 - Finished call to 'MCTS.Lingma.ask_llm_location_file.ChatGPT.get_reward' after 15.877(s), this was the 3rd time calling it. exp: 请求失败。
Message: {"code":200,"data":"{\"timestamp\":\"2024-05-19T18:14:51.665+00:00\",\"status\":500,\"error\":\"Internal Server Error\",\"path\":\"/proxy/v1/chat/completions\"}","message":"success"}

2024-05-20 02:14:53.388 | ERROR    | metagpt.utils.common:log_it:554 - Finished call to 'MCTS.Lingma.ask_llm_location_file.ChatGPT.get_reward' after 0.820(s), this was the 1st time calling it. exp: 请求失败。
Message: {"code":200,"data":"{\"timestamp\":\"2024-05-19T18:14:53.349+00:00\",\"status\":500,\"error\":\"Internal Server Error\",\"path\":\"/proxy/v1/chat/completions\"}","message":"success"}

2024-05-20 02:14:54.334 | ERROR    | metagpt.utils.common:log_it:554 - Finished call to 'MCTS.Lingma.ask_llm_location_file.ChatGPT.get_reward' after 1.763(s), this was the 1st time calling it. exp: 请求失败。
Message: {"code":200,"data":"{\"timestamp\":\"2024-05-19T18:14:54.298+00:00\",\"status\":500,\"error\":\"Internal Server Error\",\"path\":\"/proxy/v1/chat/completions\"}","message":"success"}

2024-05-20 02:14:55.751 | ERROR    | metagpt.utils.common:log_it:554 - Finished call to 'MCTS.Lingma.ask_llm_location_file.ChatGPT.get_reward' after 19.927(s), this was the 4th time calling it. exp: 请求失败。
Message: {"code":200,"data":"{\"timestamp\":\"2024-05-19T18:14:55.701+00:00\",\"status\":500,\"error\":\"Internal Server Error\",\"path\":\"/proxy/v1/chat/completions\"}","message":"success"}

2024-05-20 02:15:00.733 | ERROR    | metagpt.utils.common:log_it:554 - Finished call to 'MCTS.Lingma.ask_llm_location_file.ChatGPT.get_reward' after 8.162(s), this was the 2nd time calling it. exp: no score found for Thought: The issue discusses
2024-05-20 02:15:00.931 | ERROR    | metagpt.utils.common:log_it:554 - Finished call to 'MCTS.Lingma.ask_llm_location_file.ChatGPT.get_reward' after 8.363(s), this was the 2nd time calling it. exp: no score found for The discussion around making mixture
2024-05-20 02:15:06.136 | ERROR    | metagpt.utils.common:log_it:554 - Finished call to 'MCTS.Lingma.ask_llm_location_file.ChatGPT.get_reward' after 0.781(s), this was the 1st time calling it. exp: 请求失败。
Message: {"code":200,"data":"{\"timestamp\":\"2024-05-19T18:15:06.089+00:00\",\"status\":500,\"error\":\"Internal Server Error\",\"path\":\"/proxy/v1/chat/completions\"}","message":"success"}

2024-05-20 02:15:26.167 | ERROR    | metagpt.utils.common:log_it:554 - Finished call to 'MCTS.Lingma.ask_llm_location_file.ChatGPT.get_reward' after 0.785(s), this was the 1st time calling it. exp: 请求失败。
Message: {"code":200,"data":"{\"timestamp\":\"2024-05-19T18:15:26.120+00:00\",\"status\":500,\"error\":\"Internal Server Error\",\"path\":\"/proxy/v1/chat/completions\"}","message":"success"}

2024-05-20 02:15:27.255 | ERROR    | metagpt.utils.common:log_it:554 - Finished call to 'MCTS.Lingma.ask_llm_location_file.ChatGPT.get_reward' after 1.872(s), this was the 1st time calling it. exp: no score found for The provided code snippet from sympy
2024-05-20 02:16:10.201 | ERROR    | metagpt.utils.common:log_it:554 - Finished call to 'MCTS.Lingma.ask_llm_location_file.ChatGPT.get_reward' after 1.752(s), this was the 1st time calling it. exp: no score found for The issue reported is specific
2024-05-20 02:41:53.325 | ERROR    | metagpt.utils.common:log_it:554 - Finished call to 'MCTS.Lingma.ask_llm_location_file.ChatGPT.get_reward' after 1.746(s), this was the 1st time calling it. exp: no score found for The issue discusses
2024-05-20 02:41:53.403 | ERROR    | metagpt.utils.common:log_it:554 - Finished call to 'MCTS.Lingma.ask_llm_location_file.ChatGPT.get_reward' after 1.825(s), this was the 1st time calling it. exp: no score found for The issue described pertains
2024-05-20 02:41:53.410 | ERROR    | metagpt.utils.common:log_it:554 - Finished call to 'MCTS.Lingma.ask_llm_location_file.ChatGPT.get_reward' after 1.833(s), this was the 1st time calling it. exp: no score found for The issue revolves
2024-05-20 03:36:40.782 | ERROR    | metagpt.utils.common:log_it:554 - Finished call to 'MCTS.Lingma.ask_llm_location_file.ChatGPT.get_reward' after 305.212(s), this was the 1st time calling it. exp: 请求失败。
Message: {"code":500,"message":"服务器异常:('Connection broken: IncompleteRead(0 bytes read)', IncompleteRead(0 bytes read))"}

2024-05-20 03:48:04.385 | ERROR    | metagpt.utils.common:log_it:554 - Finished call to 'MCTS.Lingma.ask_llm_location_file.ChatGPT.get_reward' after 2.170(s), this was the 1st time calling it. exp: no score found for The
2024-05-20 03:55:35.745 | ERROR    | metagpt.utils.common:log_it:554 - Finished call to 'MCTS.Lingma.ask_llm_location_file.ChatGPT.get_reward' after 12.287(s), this was the 1st time calling it. exp: no score found for The provided code is a utility function (`check_random_state`) from scikit-learn's `sklearn/utils/validation.py` file, which is responsible for validating and converting the input `seed` into a `numpy.random.RandomState` instance. This function checks if the input is None, an integer, or an instance of `RandomState` and returns an appropriate `RandomState` instance based on the provided `seed`. This utility is commonly used across various estimators and functions within scikit-learn for consistent random state handling.

The reported issue is related to the behavior of `FeatureUnion` when working with pandas DataFrame outputs in combination with a custom transformer that aggregates data. When `set_config(transform_output="pandas")` is used, the user encounters a `ValueError` due to a length mismatch, suggesting a problem with handling the output of the transformer within a pandas DataFrame context, especially when the output dimensions change due to aggregation.

The issue at hand does not seem to be directly related to random state handling or the randomness of operations within the pipeline or `FeatureUnion`. Instead, it appears to concern the handling of output data types and shapes, particularly when switching between numpy arrays and pandas DataFrames (as influenced by the `set_config(transform_output="pandas")` setting).

Analyzing these two components:
- The `check_random_state` function is a utility for ensuring consistent randomness and does not directly interact with pandas DataFrames, nor does it manage or modify data processing pipelines.
- The reported bug involves data aggregation within a custom transformer and the subsequent handling of its output by `FeatureUnion` under different `transform_output` configurations, which is a higher-level operation concerning data structures and their manipulation rather than randomness control.

**Conclusion:**
The `check_random_state` function is not related to the reported issue, which revolves around data aggregation and `FeatureUnion` behavior in context to DataFrame output handling. The functionality of `check_random_state` is orthogonal to the process of managing transformer outputs and data frame consolidation within `FeatureUnion`. Thus the probability score that this code needs to be modified to solve the given issue is **1**.
2024-05-20 03:57:43.663 | ERROR    | metagpt.utils.common:log_it:554 - Finished call to 'MCTS.Lingma.ask_llm_location_file.ChatGPT.get_reward' after 21.747(s), this was the 1st time calling it. exp: 请求失败。
Message: {"code":200,"data":"{\"timestamp\":\"2024-05-19T19:57:43.525+00:00\",\"status\":500,\"error\":\"Internal Server Error\",\"path\":\"/proxy/v1/chat/completions\"}","message":"success"}

2024-05-20 03:58:37.544 | ERROR    | metagpt.utils.common:log_it:554 - Finished call to 'MCTS.Lingma.ask_llm_location_file.ChatGPT.get_reward' after 1.757(s), this was the 1st time calling it. exp: no score found for The issue described involves a
2024-05-20 04:21:06.857 | ERROR    | metagpt.utils.common:log_it:554 - Finished call to 'MCTS.Lingma.ask_llm_location_file.ChatGPT.get_reward' after 11.857(s), this was the 1st time calling it. exp: no score found for The reported issue deals with the display problem of an underscore in attribute names when using the Sphinx napoleon extension to generate documentation. The issue describes how an attribute named with a trailing underscore, such as `hello_`, is incorrectly rendered with an escaped underscore (`hello\_`) in the generated HTML documentation. This problem occurs when documenting Python code with the Sphinx tool, particularly when utilizing the napoleon extension to parse Google-style docstrings.

The code provided is a part of Sphinx's C++ domain implementation, specifically a method named `get_id` inside the `ASTTemplateParams` class in the `cpp.py` file. This method is responsible for generating a unique identifier for template parameters in C++ documentation generated by Sphinx. It operates by iterating over the template parameters and appending their unique identifiers to construct the final identifier string for the template parameter list.

Given the nature of the issue, which pertains to the handling of Python attribute documentation with trailing underscores in docstrings by the napoleon Sphinx extension, and the code provided, which relates to the processing of C++ domain template parameter identifiers in Sphinx, it is evident that the two are not related. The issue is specifically about the rendering of Python attribute names in documentation, while the provided code deals with internal identifier generation for C++ template parameters in Sphinx documentation.

The resolution of the issue would likely require modifications to the napoleon extension logic that processes docstrings in Python code, rather than adjustments to C++ domain handling code in Sphinx. Therefore, changes to the `get_id` method within `cpp.py` would not address the described problem of improperly escaped underscores in attribute names when using the napoleon extension for Python documentation.

Thus the probability score that this code needs to be modified to solve this issue is `1`.
2024-05-20 05:27:26.373 | ERROR    | metagpt.utils.common:log_it:554 - Finished call to 'MCTS.Lingma.ask_llm_location_file.ChatGPT.get_reward' after 21.689(s), this was the 1st time calling it. exp: 请求失败。
Message: {"code":200,"data":"{\"timestamp\":\"2024-05-19T21:27:26.236+00:00\",\"status\":500,\"error\":\"Internal Server Error\",\"path\":\"/proxy/v1/chat/completions\"}","message":"success"}

2024-05-20 05:47:10.843 | ERROR    | metagpt.utils.common:log_it:554 - Finished call to 'MCTS.Lingma.ask_llm_location_file.ChatGPT.get_reward' after 2.181(s), this was the 1st time calling it. exp: no score found for The provided global variable `
2024-05-20 06:05:40.787 | ERROR    | metagpt.utils.common:log_it:554 - Finished call to 'MCTS.Lingma.ask_llm_location_file.ChatGPT.get_reward' after 306.180(s), this was the 1st time calling it. exp: 请求失败。
Message: {"code":500,"message":"服务器异常:('Connection broken: IncompleteRead(0 bytes read)', IncompleteRead(0 bytes read))"}

2024-05-20 06:09:34.260 | ERROR    | metagpt.utils.common:log_it:554 - Finished call to 'MCTS.Lingma.ask_llm_location_file.ChatGPT.get_reward' after 1.649(s), this was the 1st time calling it. exp: no score found for The issue requests a feature where the user wants
2024-05-20 07:22:32.896 | ERROR    | metagpt.utils.common:log_it:554 - Finished call to 'MCTS.Lingma.ask_llm_location_file.ChatGPT.get_reward' after 1.800(s), this was the 1st time calling it. exp: no score found for The issue describes a `
2024-05-20 07:55:52.557 | ERROR    | metagpt.utils.common:log_it:554 - Finished call to 'MCTS.Lingma.ask_llm_location_file.ChatGPT.get_reward' after 10.098(s), this was the 1st time calling it. exp: no score found for The code provided is a function for plotting shear force in a beam in three directions (`'x'`, `'y'`, and `'z'`) from the continuum mechanics module in SymPy. This piece of code is related to structural analysis, specifically for generating plots of shear force along a beam, and it heavily relies on the user providing the direction of interest (`dir`) and any necessary substitutions for variables (`subs`) to evaluate the shear force expressions correctly.

The issue described, on the other hand, involves strange behavior in the use of the Common Subexpression Elimination (CSE) function of SymPy when dealing with expressions that involve indexing into `MatrixSymbol` objects. This discrepancy arises while attempting to optimize code generation by reducing repeated expressions through common subexpression elimination, particularly when handling symbolic matrices and working towards generating optimized numerical code.

Given the context and details of the issue and provided code:

- The issue is concerned with symbolic manipulation and optimization (specifically with matrices and indexing), aiming to efficiently handle and generate expressions involving matrix symbols.
- The provided code is part of a different functionality within the SymPy library, focused on computing and visualizing shear forces within beams, which is a topic within continuum mechanics.

**Analysis and Conclusion**:
No part of the issue is directly related to plotting shear forces or the mechanics of beams. The issue deals with symbolic manipulation of matrix expressions and code generation optimizations (CSE). The provided code is specific to a completely different functionality (3D beam analysis) within the SymPy library that does not intersect with the mechanisms of CSE or the handling of `MatrixSymbol` indexing as described in the issue.

Thus, the probability score that this code needs to be modified to solve the issue is **1**.
