2024-06-06 17:10:54.790 | ERROR    | metagpt.utils.common:log_it:554 - Finished call to 'MCTS.Lingma.ask_llm_location_file.ChatGPT.chat' after 107.213(s), this was the 1st time calling it. exp: 请求失败。
Message: {"code": 200, "data": "{\"timestamp\":\"2024-06-06T09:10:54.674+00:00\",\"status\":500,\"error\":\"Internal Server Error\",\"path\":\"/v1/chat/completions\"}", "message": "success"}
2024-06-06 17:45:00.822 | ERROR    | metagpt.utils.common:log_it:554 - Finished call to 'MCTS.Lingma.ask_llm_location_file.ChatGPT.chat' after 75.010(s), this was the 1st time calling it. exp: HTTPConnectionPool(host='47.88.8.18', port=8088): Max retries exceeded with url: /api/ask (Caused by ConnectTimeoutError(<urllib3.connection.HTTPConnection object at 0x127e2c590>, 'Connection to 47.88.8.18 timed out. (connect timeout=None)'))
2024-06-06 17:46:37.884 | ERROR    | metagpt.utils.common:log_it:554 - Finished call to 'MCTS.Lingma.ask_llm_location_file.ChatGPT.chat' after 172.070(s), this was the 2nd time calling it. exp: HTTPConnectionPool(host='47.88.8.18', port=8088): Max retries exceeded with url: /api/ask (Caused by ConnectTimeoutError(<urllib3.connection.HTTPConnection object at 0x156172610>, 'Connection to 47.88.8.18 timed out. (connect timeout=None)'))
2024-06-06 17:47:53.279 | ERROR    | metagpt.utils.common:log_it:554 - Finished call to 'MCTS.Lingma.ask_llm_location_file.ChatGPT.chat' after 247.467(s), this was the 3rd time calling it. exp: HTTPConnectionPool(host='47.88.8.18', port=8088): Max retries exceeded with url: /api/ask (Caused by ConnectTimeoutError(<urllib3.connection.HTTPConnection object at 0x1561736d0>, 'Connection to 47.88.8.18 timed out. (connect timeout=None)'))
2024-06-06 17:49:53.842 | ERROR    | metagpt.utils.common:log_it:554 - Finished call to 'MCTS.Lingma.ask_llm_location_file.ChatGPT.chat' after 368.030(s), this was the 4th time calling it. exp: HTTPConnectionPool(host='47.88.8.18', port=8088): Max retries exceeded with url: /api/ask (Caused by ConnectTimeoutError(<urllib3.connection.HTTPConnection object at 0x156171690>, 'Connection to 47.88.8.18 timed out. (connect timeout=None)'))
2024-06-06 17:51:55.817 | ERROR    | metagpt.utils.common:log_it:554 - Finished call to 'MCTS.Lingma.ask_llm_location_file.ChatGPT.chat' after 490.004(s), this was the 5th time calling it. exp: HTTPConnectionPool(host='47.88.8.18', port=8088): Max retries exceeded with url: /api/ask (Caused by ConnectTimeoutError(<urllib3.connection.HTTPConnection object at 0x156173a50>, 'Connection to 47.88.8.18 timed out. (connect timeout=None)'))
2024-06-06 17:54:09.981 | ERROR    | metagpt.utils.common:log_it:554 - Finished call to 'MCTS.Lingma.ask_llm_location_file.ChatGPT.chat' after 75.004(s), this was the 1st time calling it. exp: HTTPConnectionPool(host='47.88.8.18', port=8088): Max retries exceeded with url: /api/ask (Caused by ConnectTimeoutError(<urllib3.connection.HTTPConnection object at 0x2c56cb090>, 'Connection to 47.88.8.18 timed out. (connect timeout=None)'))
